Workbook

Sheet Pozos
A1: X-UTM | B1: Y-UTM | C1: Z_m | D1: Z MDT | E1: Cod UK | F1: Codigo Fuente | G1: Localidad | H1: Departamento | I1: Prof. Total | J1: Prof. Libre | K1: Fuente BD | L1: Observaciones | M1: Z_boca (m) | N1: Fuente_Z | O1: Dif Z_m - Z MDT (m)
A2: 580666.78 | B2: 6501918 | D2: 160.6 | E2: UK000001 | G2: museo | H2: Tacuarembó | I2: 30 | K2: MEVIR | L2: MEVIR - MATRIN | M2: =IF(AND(ISNUMBER(C2),C2>0),C2,IF(ISNUMBER(D2),D2,"")) -> 160.6 | N2: =IF(AND(ISNUMBER(C2),C2>0),"Z_m",IF(ISNUMBER(D2),"MDT IDE 2,5 m","Sin cota")) -> MDT IDE 2,5 m | O2: =IF(AND(ISNUMBER(C2),C2>0,ISNUMBER(D2)),C2-D2,"")
A3: 580631.19 | B3: 6480718.2 | D3: 180.73 | E3: UK000002 | G3: Valle Eden | H3: Tacuarembó | I3: 44 | K3: Privado | L3: TECNOAGUA | M3: =IF(AND(ISNUMBER(C3),C3>0),C3,IF(ISNUMBER(D3),D3,"")) -> 180.73 | N3: =IF(AND(ISNUMBER(C3),C3>0),"Z_m",IF(ISNUMBER(D3),"MDT IDE 2,5 m","Sin cota")) -> MDT IDE 2,5 m | O3: =IF(AND(ISNUMBER(C3),C3>0,ISNUMBER(D3)),C3-D3,"")
A4: 600463 | B4: 6512354 | D4: 249.57 | E4: UK000003 | F4: E 1604 | G4: Lambare | H4: Tacuarembó | I4: 40 | K4: Dinamige | L4: DINAMIGE PRIVADOS | M4: =IF(AND(ISNUMBER(C4),C4>0),C4,IF(ISNUMBER(D4),D4,"")) -> 249.57 | N4: =IF(AND(ISNUMBER(C4),C4>0),"Z_m",IF(ISNUMBER(D4),"MDT IDE 2,5 m","Sin cota")) -> MDT IDE 2,5 m | O4: =IF(AND(ISNUMBER(C4),C4>0,ISNUMBER(D4)),C4-D4,"")
A5: 537917 | B5: 6161747 | D5: 30.11 | E5: UK000390 | F5: SGRH-01040200692-929.001 | G5: Costas del Tigre | H5: San José | I5: 50 | K5: Dinagua | L5: Dinagua | M5: =IF(AND(ISNUMBER(C5),C5>0),C5,IF(ISNUMBER(D5),D5,"")) -> 30.11 | N5: =IF(AND(ISNUMBER(C5),C5>0),"Z_m",IF(ISNUMBER(D5),"MDT IDE 2,5 m","Sin cota")) -> MDT IDE 2,5 m | O5: =IF(AND(ISNUMBER(C5),C5>0,ISNUMBER(D5)),C5-D5,"")
A6: 600853.17 | B6: 6477474.7 | D6: 133.52 | E6: UK000005 | G6: Sauce de Tranquera | H6: Tacuarembó | I6: 45 | K6: Dinagua | L6: DJ DINAGUA | M6: =IF(AND(ISNUMBER(C6),C6>0),C6,IF(ISNUMBER(D6),D6,"")) -> 133.52 | N6: =IF(AND(ISNUMBER(C6),C6>0),"Z_m",IF(ISNUMBER(D6),"MDT IDE 2,5 m","Sin cota")) -> MDT IDE 2,5 m | O6: =IF(AND(ISNUMBER(C6),C6>0,ISNUMBER(D6)),C6-D6,"")
A7: 610505.9 | B7: 6486828 | D7: 158.71 | E7: UK000006 | G7: Rincón de Giloca | H7: Tacuarembó | I7: 55 | K7: Privado | L7: Tecnoagua | M7: =IF(AND(ISNUMBER(C7),C7>0),C7,IF(ISNUMBER(D7),D7,"")) -> 158.71 | N7: =IF(AND(ISNUMBER(C7),C7>0),"Z_m",IF(ISNUMBER(D7),"MDT IDE 2,5 m","Sin cota")) -> MDT IDE 2,5 m | O7: =IF(AND(ISNUMBER(C7),C7>0,ISNUMBER(D7)),C7-D7,"")
A8: 618653 | B8: 6498379 | D8: 195.12 | E8: UK000007 | G8: Cuchilla La Palma | H8: Tacuarembó | I8: 58 | K8: Privado | L8: TECNOAGUA | M8: =IF(AND(ISNUMBER(C8),C8>0),C8,IF(ISNUMBER(D8),D8,"")) -> 195.12 | N8: =IF(AND(ISNUMBER(C8),C8>0),"Z_m",IF(ISNUMBER(D8),"MDT IDE 2,5 m","Sin cota")) -> MDT IDE 2,5 m | O8: =IF(AND(ISNUMBER(C8),C8>0,ISNUMBER(D8)),C8-D8,"")
A9: 597801.62 | B9: 6479142 | D9: 154.78 | E9: UK000008 | F9: A 1451/1 | G9: Paso Bonilla | H9: Tacuarembó | I9: 68 | K9: Dinamige | L9: DINAMIGE FORMACION TACUAREMBO | M9: =IF(AND(ISNUMBER(C9),C9>0),C9,IF(ISNUMBER(D9),D9,"")) -> 154.78 | N9: =IF(AND(ISNUMBER(C9),C9>0),"Z_m",IF(ISNUMBER(D9),"MDT IDE 2,5 m","Sin cota")) -> MDT IDE 2,5 m | O9: =IF(AND(ISNUMBER(C9),C9>0,ISNUMBER(D9)),C9-D9,"")
A10: 575542.85 | B10: 6498196 | D10: 176.92 | E10: UK000010 | G10: Zanja de los Peñas | H10: Tacuarembó | I10: 40 | K10: Privado | L10: TECNOAGUA | M10: =IF(AND(ISNUMBER(C10),C10>0),C10,IF(ISNUMBER(D10),D10,"")) -> 176.92 | N10: =IF(AND(ISNUMBER(C10),C10>0),"Z_m",IF(ISNUMBER(D10),"MDT IDE 2,5 m","Sin cota")) -> MDT IDE 2,5 m | O10: =IF(AND(ISNUMBER(C10),C10>0,ISNUMBER(D10)),C10-D10,"")
A11: 620146.7 | B11: 6494912.5 | D11: 162.68 | E11: UK000011 | F11: A 1369/5 | G11: Cuchilla La Palma | H11: Tacuarembó | I11: 42.5 | K11: Dinamige | L11: DINAMIGE FORMACION TACUAREMBO | M11: =IF(AND(ISNUMBER(C11),C11>0),C11,IF(ISNUMBER(D11),D11,"")) -> 162.68 | N11: =IF(AND(ISNUMBER(C11),C11>0),"Z_m",IF(ISNUMBER(D11),"MDT IDE 2,5 m","Sin cota")) -> MDT IDE 2,5 m | O11: =IF(AND(ISNUMBER(C11),C11>0,ISNUMBER(D11)),C11-D11,"")
A12: 623330.92 | B12: 6483486.8 | D12: 147.1 | E12: UK000012 | F12: A 1656/31 | G12: Cuchilla del Ombu | H12: Tacuarembó | I12: 57 | K12: Dinamige | L12: DINAMIGE FORMACION TACUAREMBO | M12: =IF(AND(ISNUMBER(C12),C12>0),C12,IF(ISNUMBER(D12),D12,"")) -> 147.1 | N12: =IF(AND(ISNUMBER(C12),C12>0),"Z_m",IF(ISNUMBER(D12),"MDT IDE 2,5 m","Sin cota")) -> MDT IDE 2,5 m | O12: =IF(AND(ISNUMBER(C12),C12>0,ISNUMBER(D12)),C12-D12,"")
A13: 622983.6 | B13: 6482778.3 | D13: 135.04 | E13: UK000013 | F13: A 922/1 | G13: Cuchilla del Ombu | H13: Tacuarembó | I13: 27.5 | K13: Dinamige | L13: DINAMIGE FORMACION TACUAREMBO | M13: =IF(AND(ISNUMBER(C13),C13>0),C13,IF(ISNUMBER(D13),D13,"")) -> 135.04 | N13: =IF(AND(ISNUMBER(C13),C13>0),"Z_m",IF(ISNUMBER(D13),"MDT IDE 2,5 m","Sin cota")) -> MDT IDE 2,5 m | O13: =IF(AND(ISNUMBER(C13),C13>0,ISNUMBER(D13)),C13-D13,"")
A14: 607771.11 | B14: 6505451.2 | C14: 170 | D14: 177.49 | E14: UK000014 | F14: SAGt-5 | G14: Bañado de Rocha | H14: Tacuarembó | I14: 38 | K14: Academia | L14: Tesis Paula Collazo | M14: =IF(AND(ISNUMBER(C14),C14>0),C14,IF(ISNUMBER(D14),D14,"")) -> 170 | N14: =IF(AND(ISNUMBER(C14),C14>0),"Z_m",IF(ISNUMBER(D14),"MDT IDE 2,5 m","Sin cota")) -> Z_m | O14: =IF(AND(ISNUMBER(C14),C14>0,ISNUMBER(D14)),C14-D14,"") -> -7.49
A15: 597020.45 | B15: 6480156.1 | D15: 145.15 | E15: UK000015 | F15: A 627 | G15: Paso Bonilla | H15: Tacuarembó | I15: 112.3 | K15: Dinamige | L15: DINAMIGE FORMACION TACUAREMBO | M15: =IF(AND(ISNUMBER(C15),C15>0),C15,IF(ISNUMBER(D15),D15,"")) -> 145.15 | N15: =IF(AND(ISNUMBER(C15),C15>0),"Z_m",IF(ISNUMBER(D15),"MDT IDE 2,5 m","Sin cota")) -> MDT IDE 2,5 m | O15: =IF(AND(ISNUMBER(C15),C15>0,ISNUMBER(D15)),C15-D15,"")
A16: 587296 | B16: 6512146 | C16: 140 | D16: 180.18 | E16: UK000016 | F16: A 1504/16 // SAGt-25 | G16: Paso Ceferino | H16: Tacuarembó | I16: 34.5 | K16: Academia | L16: DINAMIGE // Tesis Paula Collazo | M16: =IF(AND(ISNUMBER(C16),C16>0),C16,IF(ISNUMBER(D16),D16,"")) -> 140 | N16: =IF(AND(ISNUMBER(C16),C16>0),"Z_m",IF(ISNUMBER(D16),"MDT IDE 2,5 m","Sin cota")) -> Z_m | O16: =IF(AND(ISNUMBER(C16),C16>0,ISNUMBER(D16)),C16-D16,"") -> -40.18
A17: 591711.36 | B17: 6507631.5 | D17: 156.66 | E17: UK000017 | F17: A 1504/13 | G17: Paso de las Carretas | H17: Tacuarembó | I17: 50.4 | K17: Dinamige | L17: DINAMIGE FORMACION TACUAREMBO | M17: =IF(AND(ISNUMBER(C17),C17>0),C17,IF(ISNUMBER(D17),D17,"")) -> 156.66 | N17: =IF(AND(ISNUMBER(C17),C17>0),"Z_m",IF(ISNUMBER(D17),"MDT IDE 2,5 m","Sin cota")) -> MDT IDE 2,5 m | O17: =IF(AND(ISNUMBER(C17),C17>0,ISNUMBER(D17)),C17-D17,"")
A18: 578934.96 | B18: 6480611.5 | D18: 176.9 | E18: UK000018 | F18: A 1085/7 | G18: Valle Eaden/Los Rosano | H18: Tacuarembó | I18: 33 | K18: Dinamige | L18: DINAMIGE FORMACION TACUAREMBO | M18: =IF(AND(ISNUMBER(C18),C18>0),C18,IF(ISNUMBER(D18),D18,"")) -> 176.9 | N18: =IF(AND(ISNUMBER(C18),C18>0),"Z_m",IF(ISNUMBER(D18),"MDT IDE 2,5 m","Sin cota")) -> MDT IDE 2,5 m | O18: =IF(AND(ISNUMBER(C18),C18>0,ISNUMBER(D18)),C18-D18,"")
A19: 599365 | B19: 6511232 | C19: 142 | D19: 158.96 | E19: UK000019 | F19: A 1504/8 // SAGt-38 | G19: Lambare | H19: Tacuarembó | I19: 31 | K19: Dinamige | L19: DINAMIGE FORMACION TACUAREMBO // Tesis Paula Collazo | M19: =IF(AND(ISNUMBER(C19),C19>0),C19,IF(ISNUMBER(D19),D19,"")) -> 142 | N19: =IF(AND(ISNUMBER(C19),C19>0),"Z_m",IF(ISNUMBER(D19),"MDT IDE 2,5 m","Sin cota")) -> Z_m | O19: =IF(AND(ISNUMBER(C19),C19>0,ISNUMBER(D19)),C19-D19,"") -> -16.96
A20: 588399 | B20: 6519151 | D20: 181.78 | E20: UK000020 | F20: A 1504/14 | G20: Paso del Medio | H20: Tacuarembó | I20: 24.2 | K20: Dinamige | L20: DINAMIGE FORMACION TACUAREMBO | M20: =IF(AND(ISNUMBER(C20),C20>0),C20,IF(ISNUMBER(D20),D20,"")) -> 181.78 | N20: =IF(AND(ISNUMBER(C20),C20>0),"Z_m",IF(ISNUMBER(D20),"MDT IDE 2,5 m","Sin cota")) -> MDT IDE 2,5 m | O20: =IF(AND(ISNUMBER(C20),C20>0,ISNUMBER(D20)),C20-D20,"")
A21: 588497.14 | B21: 6518855.3 | D21: 175.58 | E21: UK000021 | F21: 17.3.002 // SGRH-2017-10-004-0510-1-691 | G21: Paso del Medio | H21: Tacuarembó | I21: 60 | K21: Dinagua | L21: REGISTRADOS EN DINAGUA | M21: =IF(AND(ISNUMBER(C21),C21>0),C21,IF(ISNUMBER(D21),D21,"")) -> 175.58 | N21: =IF(AND(ISNUMBER(C21),C21>0),"Z_m",IF(ISNUMBER(D21),"MDT IDE 2,5 m","Sin cota")) -> MDT IDE 2,5 m | O21: =IF(AND(ISNUMBER(C21),C21>0,ISNUMBER(D21)),C21-D21,"")
A22: 589730.95 | B22: 6501755.8 | D22: 211.8 | E22: UK000022 | F22: A 1504/11 | G22: Capon de la Yerba | H22: Tacuarembó | I22: 65.4 | K22: Dinamige | L22: DINAMIGE FORMACION TACUAREMBO | M22: =IF(AND(ISNUMBER(C22),C22>0),C22,IF(ISNUMBER(D22),D22,"")) -> 211.8 | N22: =IF(AND(ISNUMBER(C22),C22>0),"Z_m",IF(ISNUMBER(D22),"MDT IDE 2,5 m","Sin cota")) -> MDT IDE 2,5 m | O22: =IF(AND(ISNUMBER(C22),C22>0,ISNUMBER(D22)),C22-D22,"")
A23: 582042.36 | B23: 6496163.2 | D23: 169.11 | E23: UK000023 | G23: EL LUJAN | H23: Tacuarembó | I23: 35 | K23: MEVIR | L23: MEVIR - MATRIN | M23: =IF(AND(ISNUMBER(C23),C23>0),C23,IF(ISNUMBER(D23),D23,"")) -> 169.11 | N23: =IF(AND(ISNUMBER(C23),C23>0),"Z_m",IF(ISNUMBER(D23),"MDT IDE 2,5 m","Sin cota")) -> MDT IDE 2,5 m | O23: =IF(AND(ISNUMBER(C23),C23>0,ISNUMBER(D23)),C23-D23,"")
A24: 598060.22 | B24: 6475615.2 | D24: 165.23 | E24: UK000024 | G24: Batovi | H24: Tacuarembó | I24: 52 | K24: Privado | L24: TECNOAGUA | M24: =IF(AND(ISNUMBER(C24),C24>0),C24,IF(ISNUMBER(D24),D24,"")) -> 165.23 | N24: =IF(AND(ISNUMBER(C24),C24>0),"Z_m",IF(ISNUMBER(D24),"MDT IDE 2,5 m","Sin cota")) -> MDT IDE 2,5 m | O24: =IF(AND(ISNUMBER(C24),C24>0,ISNUMBER(D24)),C24-D24,"")
A25: 597079 | B25: 6491662 | C25: 160 | D25: 130.45 | E25: UK000025 | F25: SAGt-43 | G25: Carumbé | H25: Tacuarembó | I25: 41 | K25: Academia | L25: Tesis Paula Collazo | M25: =IF(AND(ISNUMBER(C25),C25>0),C25,IF(ISNUMBER(D25),D25,"")) -> 160 | N25: =IF(AND(ISNUMBER(C25),C25>0),"Z_m",IF(ISNUMBER(D25),"MDT IDE 2,5 m","Sin cota")) -> Z_m | O25: =IF(AND(ISNUMBER(C25),C25>0,ISNUMBER(D25)),C25-D25,"") -> 29.55
A26: 614179.84 | B26: 6495207 | C26: 150 | D26: 150.22 | E26: UK000026 | F26: SAGt-42 | G26: Cuchilla de la Palma | H26: Tacuarembó | I26: 46 | K26: Academia | L26: Tesis Paula Collazo | M26: =IF(AND(ISNUMBER(C26),C26>0),C26,IF(ISNUMBER(D26),D26,"")) -> 150 | N26: =IF(AND(ISNUMBER(C26),C26>0),"Z_m",IF(ISNUMBER(D26),"MDT IDE 2,5 m","Sin cota")) -> Z_m | O26: =IF(AND(ISNUMBER(C26),C26>0,ISNUMBER(D26)),C26-D26,"") -> -0.22
A27: 594226.59 | B27: 6474345.2 | D27: 186.94 | E27: UK000027 | G27: Batovi | H27: Tacuarembó | I27: 47 | K27: Privado | L27: TECNOAGUA | M27: =IF(AND(ISNUMBER(C27),C27>0),C27,IF(ISNUMBER(D27),D27,"")) -> 186.94 | N27: =IF(AND(ISNUMBER(C27),C27>0),"Z_m",IF(ISNUMBER(D27),"MDT IDE 2,5 m","Sin cota")) -> MDT IDE 2,5 m | O27: =IF(AND(ISNUMBER(C27),C27>0,ISNUMBER(D27)),C27-D27,"")
A28: 607758.55 | B28: 6505282.6 | D28: 179.16 | E28: UK000028 | F28: A 578 | G28: Bañado de Rocha | H28: Tacuarembó | I28: 702 | K28: Dinamige | L28: DINAMIGE FORMACION TACUAREMBO | M28: =IF(AND(ISNUMBER(C28),C28>0),C28,IF(ISNUMBER(D28),D28,"")) -> 179.16 | N28: =IF(AND(ISNUMBER(C28),C28>0),"Z_m",IF(ISNUMBER(D28),"MDT IDE 2,5 m","Sin cota")) -> MDT IDE 2,5 m | O28: =IF(AND(ISNUMBER(C28),C28>0,ISNUMBER(D28)),C28-D28,"")
A29: 592307.24 | B29: 6474378.5 | D29: 170.35 | E29: UK000029 | G29: Batovi | H29: Tacuarembó | I29: 41 | K29: Dinagua | L29: DJ DINAGUA | M29: =IF(AND(ISNUMBER(C29),C29>0),C29,IF(ISNUMBER(D29),D29,"")) -> 170.35 | N29: =IF(AND(ISNUMBER(C29),C29>0),"Z_m",IF(ISNUMBER(D29),"MDT IDE 2,5 m","Sin cota")) -> MDT IDE 2,5 m | O29: =IF(AND(ISNUMBER(C29),C29>0,ISNUMBER(D29)),C29-D29,"")
A30: 589259.07 | B30: 6502612.3 | D30: 190.17 | E30: UK000030 | F30: A 1504/12 | G30: Poblado Capon de la Yerba | H30: Tacuarembó | I30: 53.3 | K30: Dinamige | L30: DINAMIGE FORMACION TACUAREMBO | M30: =IF(AND(ISNUMBER(C30),C30>0),C30,IF(ISNUMBER(D30),D30,"")) -> 190.17 | N30: =IF(AND(ISNUMBER(C30),C30>0),"Z_m",IF(ISNUMBER(D30),"MDT IDE 2,5 m","Sin cota")) -> MDT IDE 2,5 m | O30: =IF(AND(ISNUMBER(C30),C30>0,ISNUMBER(D30)),C30-D30,"")
A31: 593954 | B31: 6479621 | D31: 159.07 | E31: UK000031 | F31: A 1549/26 | G31: Bonilla | H31: Tacuarembó | I31: 51 | K31: Dinamige | L31: DINAMIGE FORMACION TACUAREMBO | M31: =IF(AND(ISNUMBER(C31),C31>0),C31,IF(ISNUMBER(D31),D31,"")) -> 159.07 | N31: =IF(AND(ISNUMBER(C31),C31>0),"Z_m",IF(ISNUMBER(D31),"MDT IDE 2,5 m","Sin cota")) -> MDT IDE 2,5 m | O31: =IF(AND(ISNUMBER(C31),C31>0,ISNUMBER(D31)),C31-D31,"")
A32: 594127.15 | B32: 6479349.3 | D32: 166.46 | E32: UK000032 | F32: A 1549/27 | G32: Bonilla | H32: Tacuarembó | I32: 50 | K32: Dinamige | L32: DINAMIGE FORMACION TACUAREMBO | M32: =IF(AND(ISNUMBER(C32),C32>0),C32,IF(ISNUMBER(D32),D32,"")) -> 166.46 | N32: =IF(AND(ISNUMBER(C32),C32>0),"Z_m",IF(ISNUMBER(D32),"MDT IDE 2,5 m","Sin cota")) -> MDT IDE 2,5 m | O32: =IF(AND(ISNUMBER(C32),C32>0,ISNUMBER(D32)),C32-D32,"")
A33: 594216.61 | B33: 6478358.2 | D33: 167.59 | E33: UK000033 | F33: A 1549/28 | G33: Bonilla Manzani | H33: Tacuarembó | I33: 45 | K33: Dinamige | L33: DINAMIGE FORMACION TACUAREMBO | M33: =IF(AND(ISNUMBER(C33),C33>0),C33,IF(ISNUMBER(D33),D33,"")) -> 167.59 | N33: =IF(AND(ISNUMBER(C33),C33>0),"Z_m",IF(ISNUMBER(D33),"MDT IDE 2,5 m","Sin cota")) -> MDT IDE 2,5 m | O33: =IF(AND(ISNUMBER(C33),C33>0,ISNUMBER(D33)),C33-D33,"")
A34: 593484.5 | B34: 6479807.9 | D34: 157.58 | E34: UK000034 | F34: A 1549/30 | G34: Bonilla | H34: Tacuarembó | I34: 51 | K34: Dinamige | L34: DINAMIGE FORMACION TACUAREMBO | M34: =IF(AND(ISNUMBER(C34),C34>0),C34,IF(ISNUMBER(D34),D34,"")) -> 157.58 | N34: =IF(AND(ISNUMBER(C34),C34>0),"Z_m",IF(ISNUMBER(D34),"MDT IDE 2,5 m","Sin cota")) -> MDT IDE 2,5 m | O34: =IF(AND(ISNUMBER(C34),C34>0,ISNUMBER(D34)),C34-D34,"")
A35: 597556.02 | B35: 6478807.9 | D35: 157.01 | E35: UK000035 | F35: A 1656/3 | G35: Paraje Bonilla | H35: Tacuarembó | I35: 45 | K35: Dinamige | L35: DINAMIGE FORMACION TACUAREMBO | M35: =IF(AND(ISNUMBER(C35),C35>0),C35,IF(ISNUMBER(D35),D35,"")) -> 157.01 | N35: =IF(AND(ISNUMBER(C35),C35>0),"Z_m",IF(ISNUMBER(D35),"MDT IDE 2,5 m","Sin cota")) -> MDT IDE 2,5 m | O35: =IF(AND(ISNUMBER(C35),C35>0,ISNUMBER(D35)),C35-D35,"")
A36: 588037.17 | B36: 6519440 | D36: 193.36 | E36: UK000036 | F36: A 1656/33 | G36: Paso del Medio | H36: Tacuarembó | I36: 38 | K36: Dinamige | L36: DINAMIGE FORMACION TACUAREMBO | M36: =IF(AND(ISNUMBER(C36),C36>0),C36,IF(ISNUMBER(D36),D36,"")) -> 193.36 | N36: =IF(AND(ISNUMBER(C36),C36>0),"Z_m",IF(ISNUMBER(D36),"MDT IDE 2,5 m","Sin cota")) -> MDT IDE 2,5 m | O36: =IF(AND(ISNUMBER(C36),C36>0,ISNUMBER(D36)),C36-D36,"")
A37: 596454 | B37: 6477444 | D37: 164.17 | E37: UK000037 | F37: A 1656/34 | G37: Paso Bonilla | H37: Tacuarembó | I37: 36.2 | K37: Dinamige | L37: DINAMIGE FORMACION TACUAREMBO | M37: =IF(AND(ISNUMBER(C37),C37>0),C37,IF(ISNUMBER(D37),D37,"")) -> 164.17 | N37: =IF(AND(ISNUMBER(C37),C37>0),"Z_m",IF(ISNUMBER(D37),"MDT IDE 2,5 m","Sin cota")) -> MDT IDE 2,5 m | O37: =IF(AND(ISNUMBER(C37),C37>0,ISNUMBER(D37)),C37-D37,"")
A38: 596492.12 | B38: 6477452.7 | D38: 162.58 | E38: UK000038 | F38: A 1656/8 | G38: Paraje Lujan | H38: Tacuarembó | I38: 40 | K38: Dinamige | L38: DINAMIGE FORMACION TACUAREMBO | M38: =IF(AND(ISNUMBER(C38),C38>0),C38,IF(ISNUMBER(D38),D38,"")) -> 162.58 | N38: =IF(AND(ISNUMBER(C38),C38>0),"Z_m",IF(ISNUMBER(D38),"MDT IDE 2,5 m","Sin cota")) -> MDT IDE 2,5 m | O38: =IF(AND(ISNUMBER(C38),C38>0,ISNUMBER(D38)),C38-D38,"")
A39: 610124.84 | B39: 6492724.7 | D39: 146.85 | E39: UK000039 | F39: A 1400/1 | G39: Estancia La Magnolia | H39: Tacuarembó | I39: 66 | K39: Dinamige | L39: DINAMIGE FORMACION TACUAREMBO | M39: =IF(AND(ISNUMBER(C39),C39>0),C39,IF(ISNUMBER(D39),D39,"")) -> 146.85 | N39: =IF(AND(ISNUMBER(C39),C39>0),"Z_m",IF(ISNUMBER(D39),"MDT IDE 2,5 m","Sin cota")) -> MDT IDE 2,5 m | O39: =IF(AND(ISNUMBER(C39),C39>0,ISNUMBER(D39)),C39-D39,"")
A40: 611157 | B40: 6491178 | D40: 146.45 | E40: UK000040 | F40: A 1400/2 | G40: Estancia La Magnolia | H40: Tacuarembó | I40: 66 | K40: Dinamige | L40: DINAMIGE FORMACION TACUAREMBO | M40: =IF(AND(ISNUMBER(C40),C40>0),C40,IF(ISNUMBER(D40),D40,"")) -> 146.45 | N40: =IF(AND(ISNUMBER(C40),C40>0),"Z_m",IF(ISNUMBER(D40),"MDT IDE 2,5 m","Sin cota")) -> MDT IDE 2,5 m | O40: =IF(AND(ISNUMBER(C40),C40>0,ISNUMBER(D40)),C40-D40,"")
...

Sheet Hidráulica
A1: Cod UK | B1: Caudal | C1: NE_m | D1: NE Acotado | E1: ND-m | F1: Fecha | G1: Año | H1: Fuente | I1: Observaciones
A2: UK000001 | B2: 4 | C2: 9.5 | E2: 20.2 | H2: MEVIR
A3: UK000002 | B3: 4 | C3: 23.5 | H3: Privado
A4: UK000003 | C4: 11 | H4: Privado
A5: UK000004 | H5: Privado
A6: UK000005 | B6: 1 | H6: Dinagua
A7: UK000006 | B7: 1 | C7: 20 | H7: Privado
A8: UK000007 | B8: 10 | C8: 28.5 | H8: Privado
A9: UK000008 | B9: 2 | C9: 18.2 | E9: 40 | H9: Dinamige
A10: UK000161 | B10: 1.5 | C10: 25 | H10: Privado
A11: UK000010 | B11: 4.8 | C11: 0.1 | E11: 3 | H11: Privado
A12: UK000011 | B12: 7.5 | C12: 24.4 | E12: 35.4 | H12: Dinamige
A13: UK000012 | B13: 0.36 | C13: 7 | D13: 137 | E13: 48 | H13: Dinamige
A14: UK000013 | B14: 2.5 | C14: 8.4 | E14: 20 | H14: Dinamige
A15: UK000014 | B15: 6 | C15: 9.3 | D15: 160.8 | H15: Academia
A16: UK000015 | B16: 1.9 | C16: 13.5 | E16: 84.75 | H16: Dinamige
A17: UK000016 | B17: 3 | C17: 16.5 | D17: 123.5 | H17: Academia
A18: UK000017 | B18: 3.8 | C18: 13 | E18: 27.4 | H18: Dinamige
A19: UK000018 | B19: 5.2 | C19: 5.2 | E19: 28 | H19: Dinamige
A20: UK000019 | B20: 6.6 | C20: 10.75 | E20: 18.2 | H20: Academia
A21: UK000019 | C21: 11.4 | D21: 130.6 | H21: Academia
A22: UK000020 | B22: 5.7 | C22: 12.05 | E22: 18 | H22: Dinamige
A23: UK001800 | B23: 3.8 | C23: 16.5 | D23: 123.5 | E23: 31.05 | H23: Dinagua
A24: UK000022 | B24: 3.3 | C24: 28 | E24: 46.6 | H24: Dinamige
A25: UK000023 | B25: 6 | C25: 9 | E25: 14 | H25: Privado
A26: UK000024 | B26: 0.8 | C26: 22.5 | H26: Privado
A27: UK000025 | B27: 1.8 | C27: 8.8 | D27: 151.2 | E27: 24 | H27: Academia
A28: UK000025 | C28: 9.16 | F28: 46105 | G28: 2026 | H28: Dinagua
A29: UK000026 | B29: 2.5 | C29: 14 | D29: 136 | E29: 24 | H29: Academia
A30: UK000027 | B30: 2.4 | C30: 13.58 | E30: 24.43 | H30: Privado
A31: UK000028 | B31: 7.2 | C31: 11.5 | E31: 19 | H31: Dinamige
A32: UK000029 | B32: 2.4 | C32: 16.72 | E32: 20.52 | H32: Dinagua
A33: UK000030 | B33: 5.2 | C33: 20.5 | E33: 38 | H33: Dinamige
A34: UK000031 | B34: 3.2 | C34: 13.5 | E34: 40 | H34: Dinamige
A35: UK000032 | B35: 3.2 | C35: 16 | E35: 40 | H35: Dinamige
A36: UK000033 | B36: 1.2 | C36: 18 | E36: 35 | H36: Dinamige
A37: UK000034 | B37: 3.3 | C37: 15 | E37: 40 | H37: Dinamige
A38: UK000035 | B38: 2 | H38: Dinamige
A39: UK000036 | B39: 0.6 | C39: 14 | E39: 27 | H39: Dinamige
A40: UK000037 | B40: 2.4 | C40: 23.2 | E40: 32 | H40: Dinamige
...

Sheet Ubic. Napas_m
A1: Cod UK | B1: Inicio | C1: Fin | D1: Comentarios | E1: Fuente BD | F1: Z_boca (m) | G1: Inicio Acotado | H1: Fin Acotado
A2: UK000001 | E2: MEVIR - MATRIN | F2: =IFERROR(INDEX(Pozos!$M$2:$M$1852,MATCH(A2,Pozos!$E$2:$E$1852,0)),"") -> 160.6 | G2: =IF(AND(ISNUMBER(B2),ISNUMBER($F2)),$F2-B2,"") | H2: =IF(AND(ISNUMBER(C2),ISNUMBER($F2)),$F2-C2,"")
A3: UK000002 | E3: TECNOAGUA | F3: =IFERROR(INDEX(Pozos!$M$2:$M$1852,MATCH(A3,Pozos!$E$2:$E$1852,0)),"") -> 180.73 | G3: =IF(AND(ISNUMBER(B3),ISNUMBER($F3)),$F3-B3,"") | H3: =IF(AND(ISNUMBER(C3),ISNUMBER($F3)),$F3-C3,"")
A4: UK000003 | E4: DINAMIGE PRIVADOS | F4: =IFERROR(INDEX(Pozos!$M$2:$M$1852,MATCH(A4,Pozos!$E$2:$E$1852,0)),"") -> 249.57 | G4: =IF(AND(ISNUMBER(B4),ISNUMBER($F4)),$F4-B4,"") | H4: =IF(AND(ISNUMBER(C4),ISNUMBER($F4)),$F4-C4,"")
A5: UK000004 | E5: DINAMIGE PRIVADOS | F5: =IFERROR(INDEX(Pozos!$M$2:$M$1852,MATCH(A5,Pozos!$E$2:$E$1852,0)),"") -> 254.03 | G5: =IF(AND(ISNUMBER(B5),ISNUMBER($F5)),$F5-B5,"") | H5: =IF(AND(ISNUMBER(C5),ISNUMBER($F5)),$F5-C5,"")
A6: UK000005 | E6: DJ DINAGUA | F6: =IFERROR(INDEX(Pozos!$M$2:$M$1852,MATCH(A6,Pozos!$E$2:$E$1852,0)),"") -> 133.52 | G6: =IF(AND(ISNUMBER(B6),ISNUMBER($F6)),$F6-B6,"") | H6: =IF(AND(ISNUMBER(C6),ISNUMBER($F6)),$F6-C6,"")
A7: UK000006 | E7: Tecnoagua | F7: =IFERROR(INDEX(Pozos!$M$2:$M$1852,MATCH(A7,Pozos!$E$2:$E$1852,0)),"") -> 158.71 | G7: =IF(AND(ISNUMBER(B7),ISNUMBER($F7)),$F7-B7,"") | H7: =IF(AND(ISNUMBER(C7),ISNUMBER($F7)),$F7-C7,"")
A8: UK000007 | E8: TECNOAGUA | F8: =IFERROR(INDEX(Pozos!$M$2:$M$1852,MATCH(A8,Pozos!$E$2:$E$1852,0)),"") -> 195.12 | G8: =IF(AND(ISNUMBER(B8),ISNUMBER($F8)),$F8-B8,"") | H8: =IF(AND(ISNUMBER(C8),ISNUMBER($F8)),$F8-C8,"")
A9: UK000008 | E9: DINAMIGE FORMACION TACUAREMBO | F9: =IFERROR(INDEX(Pozos!$M$2:$M$1852,MATCH(A9,Pozos!$E$2:$E$1852,0)),"") -> 154.78 | G9: =IF(AND(ISNUMBER(B9),ISNUMBER($F9)),$F9-B9,"") | H9: =IF(AND(ISNUMBER(C9),ISNUMBER($F9)),$F9-C9,"")
A10: UK000161 | E10: TECNOAGUA | F10: =IFERROR(INDEX(Pozos!$M$2:$M$1852,MATCH(A10,Pozos!$E$2:$E$1852,0)),"") -> 164.7 | G10: =IF(AND(ISNUMBER(B10),ISNUMBER($F10)),$F10-B10,"") | H10: =IF(AND(ISNUMBER(C10),ISNUMBER($F10)),$F10-C10,"")
A11: UK000010 | E11: TECNOAGUA | F11: =IFERROR(INDEX(Pozos!$M$2:$M$1852,MATCH(A11,Pozos!$E$2:$E$1852,0)),"") -> 176.92 | G11: =IF(AND(ISNUMBER(B11),ISNUMBER($F11)),$F11-B11,"") | H11: =IF(AND(ISNUMBER(C11),ISNUMBER($F11)),$F11-C11,"")
A12: UK000011 | E12: DINAMIGE FORMACION TACUAREMBO | F12: =IFERROR(INDEX(Pozos!$M$2:$M$1852,MATCH(A12,Pozos!$E$2:$E$1852,0)),"") -> 162.68 | G12: =IF(AND(ISNUMBER(B12),ISNUMBER($F12)),$F12-B12,"") | H12: =IF(AND(ISNUMBER(C12),ISNUMBER($F12)),$F12-C12,"")
A13: UK000012 | B13: 33 | C13: 36.4 | E13: DINAMIGE FORMACION TACUAREMBO | F13: =IFERROR(INDEX(Pozos!$M$2:$M$1852,MATCH(A13,Pozos!$E$2:$E$1852,0)),"") -> 147.1 | G13: =IF(AND(ISNUMBER(B13),ISNUMBER($F13)),$F13-B13,"") -> 114.1 | H13: =IF(AND(ISNUMBER(C13),ISNUMBER($F13)),$F13-C13,"") -> 110.7
A14: UK000013 | B14: 15.5 | D14: no se sabe si el dato es de incio o fin | E14: DINAMIGE FORMACION TACUAREMBO | F14: =IFERROR(INDEX(Pozos!$M$2:$M$1852,MATCH(A14,Pozos!$E$2:$E$1852,0)),"") -> 135.04 | G14: =IF(AND(ISNUMBER(B14),ISNUMBER($F14)),$F14-B14,"") -> 119.54 | H14: =IF(AND(ISNUMBER(C14),ISNUMBER($F14)),$F14-C14,"")
A15: UK000014 | E15: Tesis Paula Collazo | F15: =IFERROR(INDEX(Pozos!$M$2:$M$1852,MATCH(A15,Pozos!$E$2:$E$1852,0)),"") -> 170 | G15: =IF(AND(ISNUMBER(B15),ISNUMBER($F15)),$F15-B15,"") | H15: =IF(AND(ISNUMBER(C15),ISNUMBER($F15)),$F15-C15,"")
A16: UK000015 | B16: 105 | C16: 33.5 | E16: DINAMIGE FORMACION TACUAREMBO | F16: =IFERROR(INDEX(Pozos!$M$2:$M$1852,MATCH(A16,Pozos!$E$2:$E$1852,0)),"") -> 145.15 | G16: =IF(AND(ISNUMBER(B16),ISNUMBER($F16)),$F16-B16,"") -> 40.15 | H16: =IF(AND(ISNUMBER(C16),ISNUMBER($F16)),$F16-C16,"") -> 111.65
A17: UK000016 | E17: DINAMIGE // Tesis Paula Collazo | F17: =IFERROR(INDEX(Pozos!$M$2:$M$1852,MATCH(A17,Pozos!$E$2:$E$1852,0)),"") -> 140 | G17: =IF(AND(ISNUMBER(B17),ISNUMBER($F17)),$F17-B17,"") | H17: =IF(AND(ISNUMBER(C17),ISNUMBER($F17)),$F17-C17,"")
A18: UK000017 | E18: DINAMIGE FORMACION TACUAREMBO | F18: =IFERROR(INDEX(Pozos!$M$2:$M$1852,MATCH(A18,Pozos!$E$2:$E$1852,0)),"") -> 156.66 | G18: =IF(AND(ISNUMBER(B18),ISNUMBER($F18)),$F18-B18,"") | H18: =IF(AND(ISNUMBER(C18),ISNUMBER($F18)),$F18-C18,"")
A19: UK000018 | E19: DINAMIGE FORMACION TACUAREMBO | F19: =IFERROR(INDEX(Pozos!$M$2:$M$1852,MATCH(A19,Pozos!$E$2:$E$1852,0)),"") -> 176.9 | G19: =IF(AND(ISNUMBER(B19),ISNUMBER($F19)),$F19-B19,"") | H19: =IF(AND(ISNUMBER(C19),ISNUMBER($F19)),$F19-C19,"")
A20: UK000019 | B20: 26 | D20: no se sabe si el dato es de incio o fin | E20: DINAMIGE FORMACION TACUAREMBO // Tesis Paula Collazo | F20: =IFERROR(INDEX(Pozos!$M$2:$M$1852,MATCH(A20,Pozos!$E$2:$E$1852,0)),"") -> 142 | G20: =IF(AND(ISNUMBER(B20),ISNUMBER($F20)),$F20-B20,"") -> 116 | H20: =IF(AND(ISNUMBER(C20),ISNUMBER($F20)),$F20-C20,"")
A21: UK000020 | B21: 20 | C21: 23 | E21: DINAMIGE FORMACION TACUAREMBO | F21: =IFERROR(INDEX(Pozos!$M$2:$M$1852,MATCH(A21,Pozos!$E$2:$E$1852,0)),"") -> 181.78 | G21: =IF(AND(ISNUMBER(B21),ISNUMBER($F21)),$F21-B21,"") -> 161.78 | H21: =IF(AND(ISNUMBER(C21),ISNUMBER($F21)),$F21-C21,"") -> 158.78
A22: UK001800 | E22: REGISTRADOS EN DINAGUA | F22: =IFERROR(INDEX(Pozos!$M$2:$M$1852,MATCH(A22,Pozos!$E$2:$E$1852,0)),"") -> 174.99 | G22: =IF(AND(ISNUMBER(B22),ISNUMBER($F22)),$F22-B22,"") | H22: =IF(AND(ISNUMBER(C22),ISNUMBER($F22)),$F22-C22,"")
A23: UK000022 | B23: 47 | C23: 49.5 | E23: DINAMIGE FORMACION TACUAREMBO | F23: =IFERROR(INDEX(Pozos!$M$2:$M$1852,MATCH(A23,Pozos!$E$2:$E$1852,0)),"") -> 211.8 | G23: =IF(AND(ISNUMBER(B23),ISNUMBER($F23)),$F23-B23,"") -> 164.8 | H23: =IF(AND(ISNUMBER(C23),ISNUMBER($F23)),$F23-C23,"") -> 162.3
A24: UK000023 | E24: MEVIR - MATRIN | F24: =IFERROR(INDEX(Pozos!$M$2:$M$1852,MATCH(A24,Pozos!$E$2:$E$1852,0)),"") -> 169.11 | G24: =IF(AND(ISNUMBER(B24),ISNUMBER($F24)),$F24-B24,"") | H24: =IF(AND(ISNUMBER(C24),ISNUMBER($F24)),$F24-C24,"")
A25: UK000024 | B25: 35 | C25: 36 | E25: TECNOAGUA | F25: =IFERROR(INDEX(Pozos!$M$2:$M$1852,MATCH(A25,Pozos!$E$2:$E$1852,0)),"") -> 165.23 | G25: =IF(AND(ISNUMBER(B25),ISNUMBER($F25)),$F25-B25,"") -> 130.23 | H25: =IF(AND(ISNUMBER(C25),ISNUMBER($F25)),$F25-C25,"") -> 129.23
A26: UK000024 | B26: 46 | C26: 47 | E26: TECNOAGUA | F26: =IFERROR(INDEX(Pozos!$M$2:$M$1852,MATCH(A26,Pozos!$E$2:$E$1852,0)),"") -> 165.23 | G26: =IF(AND(ISNUMBER(B26),ISNUMBER($F26)),$F26-B26,"") -> 119.23 | H26: =IF(AND(ISNUMBER(C26),ISNUMBER($F26)),$F26-C26,"") -> 118.23
A27: UK000025 | E27: Tesis Paula Collazo | F27: =IFERROR(INDEX(Pozos!$M$2:$M$1852,MATCH(A27,Pozos!$E$2:$E$1852,0)),"") -> 160 | G27: =IF(AND(ISNUMBER(B27),ISNUMBER($F27)),$F27-B27,"") | H27: =IF(AND(ISNUMBER(C27),ISNUMBER($F27)),$F27-C27,"")
A28: UK000026 | E28: Tesis Paula Collazo | F28: =IFERROR(INDEX(Pozos!$M$2:$M$1852,MATCH(A28,Pozos!$E$2:$E$1852,0)),"") -> 150 | G28: =IF(AND(ISNUMBER(B28),ISNUMBER($F28)),$F28-B28,"") | H28: =IF(AND(ISNUMBER(C28),ISNUMBER($F28)),$F28-C28,"")
A29: UK000027 | E29: TECNOAGUA | F29: =IFERROR(INDEX(Pozos!$M$2:$M$1852,MATCH(A29,Pozos!$E$2:$E$1852,0)),"") -> 186.94 | G29: =IF(AND(ISNUMBER(B29),ISNUMBER($F29)),$F29-B29,"") | H29: =IF(AND(ISNUMBER(C29),ISNUMBER($F29)),$F29-C29,"")
A30: UK000028 | B30: 1.4 | C30: 13.2 | E30: DINAMIGE FORMACION TACUAREMBO | F30: =IFERROR(INDEX(Pozos!$M$2:$M$1852,MATCH(A30,Pozos!$E$2:$E$1852,0)),"") -> 179.16 | G30: =IF(AND(ISNUMBER(B30),ISNUMBER($F30)),$F30-B30,"") -> 177.76 | H30: =IF(AND(ISNUMBER(C30),ISNUMBER($F30)),$F30-C30,"") -> 165.96
A31: UK000029 | B31: 19 | C31: 20 | E31: DJ DINAGUA | F31: =IFERROR(INDEX(Pozos!$M$2:$M$1852,MATCH(A31,Pozos!$E$2:$E$1852,0)),"") -> 170.35 | G31: =IF(AND(ISNUMBER(B31),ISNUMBER($F31)),$F31-B31,"") -> 151.35 | H31: =IF(AND(ISNUMBER(C31),ISNUMBER($F31)),$F31-C31,"") -> 150.35
A32: UK000029 | B32: 36 | C32: 37 | E32: DJ DINAGUA | F32: =IFERROR(INDEX(Pozos!$M$2:$M$1852,MATCH(A32,Pozos!$E$2:$E$1852,0)),"") -> 170.35 | G32: =IF(AND(ISNUMBER(B32),ISNUMBER($F32)),$F32-B32,"") -> 134.35 | H32: =IF(AND(ISNUMBER(C32),ISNUMBER($F32)),$F32-C32,"") -> 133.35
A33: UK000030 | B33: 44 | D33: no se sabe si el dato es de incio o fin | E33: DINAMIGE FORMACION TACUAREMBO | F33: =IFERROR(INDEX(Pozos!$M$2:$M$1852,MATCH(A33,Pozos!$E$2:$E$1852,0)),"") -> 190.17 | G33: =IF(AND(ISNUMBER(B33),ISNUMBER($F33)),$F33-B33,"") -> 146.17 | H33: =IF(AND(ISNUMBER(C33),ISNUMBER($F33)),$F33-C33,"")
A34: UK000031 | B34: 19 | D34: no se sabe si el dato es de incio o fin | E34: DINAMIGE FORMACION TACUAREMBO | F34: =IFERROR(INDEX(Pozos!$M$2:$M$1852,MATCH(A34,Pozos!$E$2:$E$1852,0)),"") -> 159.07 | G34: =IF(AND(ISNUMBER(B34),ISNUMBER($F34)),$F34-B34,"") -> 140.07 | H34: =IF(AND(ISNUMBER(C34),ISNUMBER($F34)),$F34-C34,"")
A35: UK000032 | B35: 19.39 | D35: no se sabe si el dato es de incio o fin | E35: DINAMIGE FORMACION TACUAREMBO | F35: =IFERROR(INDEX(Pozos!$M$2:$M$1852,MATCH(A35,Pozos!$E$2:$E$1852,0)),"") -> 166.46 | G35: =IF(AND(ISNUMBER(B35),ISNUMBER($F35)),$F35-B35,"") -> 147.07 | H35: =IF(AND(ISNUMBER(C35),ISNUMBER($F35)),$F35-C35,"")
A36: UK000033 | B36: 38 | D36: no se sabe si el dato es de incio o fin | E36: DINAMIGE FORMACION TACUAREMBO | F36: =IFERROR(INDEX(Pozos!$M$2:$M$1852,MATCH(A36,Pozos!$E$2:$E$1852,0)),"") -> 167.59 | G36: =IF(AND(ISNUMBER(B36),ISNUMBER($F36)),$F36-B36,"") -> 129.59 | H36: =IF(AND(ISNUMBER(C36),ISNUMBER($F36)),$F36-C36,"")
A37: UK000034 | B37: 44 | D37: no se sabe si el dato es de incio o fin | E37: DINAMIGE FORMACION TACUAREMBO | F37: =IFERROR(INDEX(Pozos!$M$2:$M$1852,MATCH(A37,Pozos!$E$2:$E$1852,0)),"") -> 157.58 | G37: =IF(AND(ISNUMBER(B37),ISNUMBER($F37)),$F37-B37,"") -> 113.58 | H37: =IF(AND(ISNUMBER(C37),ISNUMBER($F37)),$F37-C37,"")
A38: UK000035 | B38: 40 | D38: no se sabe si el dato es de incio o fin | E38: DINAMIGE FORMACION TACUAREMBO | F38: =IFERROR(INDEX(Pozos!$M$2:$M$1852,MATCH(A38,Pozos!$E$2:$E$1852,0)),"") -> 157.01 | G38: =IF(AND(ISNUMBER(B38),ISNUMBER($F38)),$F38-B38,"") -> 117.01 | H38: =IF(AND(ISNUMBER(C38),ISNUMBER($F38)),$F38-C38,"")
A39: UK000036 | B39: 25 | C39: 27 | E39: DINAMIGE FORMACION TACUAREMBO | F39: =IFERROR(INDEX(Pozos!$M$2:$M$1852,MATCH(A39,Pozos!$E$2:$E$1852,0)),"") -> 193.36 | G39: =IF(AND(ISNUMBER(B39),ISNUMBER($F39)),$F39-B39,"") -> 168.36 | H39: =IF(AND(ISNUMBER(C39),ISNUMBER($F39)),$F39-C39,"") -> 166.36
A40: UK000037 | B40: 27 | C40: 30 | E40: DINAMIGE FORMACION TACUAREMBO | F40: =IFERROR(INDEX(Pozos!$M$2:$M$1852,MATCH(A40,Pozos!$E$2:$E$1852,0)),"") -> 164.17 | G40: =IF(AND(ISNUMBER(B40),ISNUMBER($F40)),$F40-B40,"") -> 137.17 | H40: =IF(AND(ISNUMBER(C40),ISNUMBER($F40)),$F40-C40,"") -> 134.17
...

Sheet Filtros_m
A1: Cod UK | B1: Inicio | C1: Fin | D1: Comentarios | E1: Fuente BD | F1: Z_boca (m) | G1: Inicio Acotado | H1: Fin Acotado
A2: UK000001 | E2: MEVIR - MATRIN | F2: =IFERROR(INDEX(Pozos!$M$2:$M$1852,MATCH(A2,Pozos!$E$2:$E$1852,0)),"") -> 160.6 | G2: =IF(AND(ISNUMBER(B2),ISNUMBER($F2)),$F2-B2,"") | H2: =IF(AND(ISNUMBER(C2),ISNUMBER($F2)),$F2-C2,"")
A3: UK000002 | E3: TECNOAGUA | F3: =IFERROR(INDEX(Pozos!$M$2:$M$1852,MATCH(A3,Pozos!$E$2:$E$1852,0)),"") -> 180.73 | G3: =IF(AND(ISNUMBER(B3),ISNUMBER($F3)),$F3-B3,"") | H3: =IF(AND(ISNUMBER(C3),ISNUMBER($F3)),$F3-C3,"")
A4: UK000003 | E4: DINAMIGE PRIVADOS | F4: =IFERROR(INDEX(Pozos!$M$2:$M$1852,MATCH(A4,Pozos!$E$2:$E$1852,0)),"") -> 249.57 | G4: =IF(AND(ISNUMBER(B4),ISNUMBER($F4)),$F4-B4,"") | H4: =IF(AND(ISNUMBER(C4),ISNUMBER($F4)),$F4-C4,"")
A5: UK000004 | E5: DINAMIGE PRIVADOS | F5: =IFERROR(INDEX(Pozos!$M$2:$M$1852,MATCH(A5,Pozos!$E$2:$E$1852,0)),"") -> 254.03 | G5: =IF(AND(ISNUMBER(B5),ISNUMBER($F5)),$F5-B5,"") | H5: =IF(AND(ISNUMBER(C5),ISNUMBER($F5)),$F5-C5,"")
A6: UK000005 | E6: DJ DINAGUA | F6: =IFERROR(INDEX(Pozos!$M$2:$M$1852,MATCH(A6,Pozos!$E$2:$E$1852,0)),"") -> 133.52 | G6: =IF(AND(ISNUMBER(B6),ISNUMBER($F6)),$F6-B6,"") | H6: =IF(AND(ISNUMBER(C6),ISNUMBER($F6)),$F6-C6,"")
A7: UK000006 | E7: Tecnoagua | F7: =IFERROR(INDEX(Pozos!$M$2:$M$1852,MATCH(A7,Pozos!$E$2:$E$1852,0)),"") -> 158.71 | G7: =IF(AND(ISNUMBER(B7),ISNUMBER($F7)),$F7-B7,"") | H7: =IF(AND(ISNUMBER(C7),ISNUMBER($F7)),$F7-C7,"")
A8: UK000007 | E8: TECNOAGUA | F8: =IFERROR(INDEX(Pozos!$M$2:$M$1852,MATCH(A8,Pozos!$E$2:$E$1852,0)),"") -> 195.12 | G8: =IF(AND(ISNUMBER(B8),ISNUMBER($F8)),$F8-B8,"") | H8: =IF(AND(ISNUMBER(C8),ISNUMBER($F8)),$F8-C8,"")
A9: UK000008 | E9: DINAMIGE FORMACION TACUAREMBO | F9: =IFERROR(INDEX(Pozos!$M$2:$M$1852,MATCH(A9,Pozos!$E$2:$E$1852,0)),"") -> 154.78 | G9: =IF(AND(ISNUMBER(B9),ISNUMBER($F9)),$F9-B9,"") | H9: =IF(AND(ISNUMBER(C9),ISNUMBER($F9)),$F9-C9,"")
A10: UK000161 | E10: TECNOAGUA | F10: =IFERROR(INDEX(Pozos!$M$2:$M$1852,MATCH(A10,Pozos!$E$2:$E$1852,0)),"") -> 164.7 | G10: =IF(AND(ISNUMBER(B10),ISNUMBER($F10)),$F10-B10,"") | H10: =IF(AND(ISNUMBER(C10),ISNUMBER($F10)),$F10-C10,"")
A11: UK000010 | B11: 20 | C11: 22 | E11: TECNOAGUA | F11: =IFERROR(INDEX(Pozos!$M$2:$M$1852,MATCH(A11,Pozos!$E$2:$E$1852,0)),"") -> 176.92 | G11: =IF(AND(ISNUMBER(B11),ISNUMBER($F11)),$F11-B11,"") -> 156.92 | H11: =IF(AND(ISNUMBER(C11),ISNUMBER($F11)),$F11-C11,"") -> 154.92
A12: UK000010 | B12: 36 | C12: 38 | E12: TECNOAGUA | F12: =IFERROR(INDEX(Pozos!$M$2:$M$1852,MATCH(A12,Pozos!$E$2:$E$1852,0)),"") -> 176.92 | G12: =IF(AND(ISNUMBER(B12),ISNUMBER($F12)),$F12-B12,"") -> 140.92 | H12: =IF(AND(ISNUMBER(C12),ISNUMBER($F12)),$F12-C12,"") -> 138.92
A13: UK000011 | B13: 25 | C13: 26 | E13: DINAMIGE FORMACION TACUAREMBO | F13: =IFERROR(INDEX(Pozos!$M$2:$M$1852,MATCH(A13,Pozos!$E$2:$E$1852,0)),"") -> 162.68 | G13: =IF(AND(ISNUMBER(B13),ISNUMBER($F13)),$F13-B13,"") -> 137.68 | H13: =IF(AND(ISNUMBER(C13),ISNUMBER($F13)),$F13-C13,"") -> 136.68
A14: UK000011 | B14: 28 | C14: 30 | E14: DINAMIGE FORMACION TACUAREMBO | F14: =IFERROR(INDEX(Pozos!$M$2:$M$1852,MATCH(A14,Pozos!$E$2:$E$1852,0)),"") -> 162.68 | G14: =IF(AND(ISNUMBER(B14),ISNUMBER($F14)),$F14-B14,"") -> 134.68 | H14: =IF(AND(ISNUMBER(C14),ISNUMBER($F14)),$F14-C14,"") -> 132.68
A15: UK000011 | B15: 38 | C15: 40 | E15: DINAMIGE FORMACION TACUAREMBO | F15: =IFERROR(INDEX(Pozos!$M$2:$M$1852,MATCH(A15,Pozos!$E$2:$E$1852,0)),"") -> 162.68 | G15: =IF(AND(ISNUMBER(B15),ISNUMBER($F15)),$F15-B15,"") -> 124.68 | H15: =IF(AND(ISNUMBER(C15),ISNUMBER($F15)),$F15-C15,"") -> 122.68
A16: UK000012 | B16: 33.86 | C16: 36.4 | E16: DINAMIGE FORMACION TACUAREMBO | F16: =IFERROR(INDEX(Pozos!$M$2:$M$1852,MATCH(A16,Pozos!$E$2:$E$1852,0)),"") -> 147.1 | G16: =IF(AND(ISNUMBER(B16),ISNUMBER($F16)),$F16-B16,"") -> 113.24 | H16: =IF(AND(ISNUMBER(C16),ISNUMBER($F16)),$F16-C16,"") -> 110.7
A17: UK000013 | B17: 13.8 | C17: 16.8 | E17: DINAMIGE FORMACION TACUAREMBO | F17: =IFERROR(INDEX(Pozos!$M$2:$M$1852,MATCH(A17,Pozos!$E$2:$E$1852,0)),"") -> 135.04 | G17: =IF(AND(ISNUMBER(B17),ISNUMBER($F17)),$F17-B17,"") -> 121.24 | H17: =IF(AND(ISNUMBER(C17),ISNUMBER($F17)),$F17-C17,"") -> 118.24
A18: UK000014 | B18: 29 | C18: 30 | E18: Tesis Paula Collazo | F18: =IFERROR(INDEX(Pozos!$M$2:$M$1852,MATCH(A18,Pozos!$E$2:$E$1852,0)),"") -> 170 | G18: =IF(AND(ISNUMBER(B18),ISNUMBER($F18)),$F18-B18,"") -> 141 | H18: =IF(AND(ISNUMBER(C18),ISNUMBER($F18)),$F18-C18,"") -> 140
A19: UK000014 | B19: 33 | C19: 35 | E19: Tesis Paula Collazo | F19: =IFERROR(INDEX(Pozos!$M$2:$M$1852,MATCH(A19,Pozos!$E$2:$E$1852,0)),"") -> 170 | G19: =IF(AND(ISNUMBER(B19),ISNUMBER($F19)),$F19-B19,"") -> 137 | H19: =IF(AND(ISNUMBER(C19),ISNUMBER($F19)),$F19-C19,"") -> 135
A20: UK000014 | B20: 40 | C20: 41 | E20: Tesis Paula Collazo | F20: =IFERROR(INDEX(Pozos!$M$2:$M$1852,MATCH(A20,Pozos!$E$2:$E$1852,0)),"") -> 170 | G20: =IF(AND(ISNUMBER(B20),ISNUMBER($F20)),$F20-B20,"") -> 130 | H20: =IF(AND(ISNUMBER(C20),ISNUMBER($F20)),$F20-C20,"") -> 129
A21: UK000015 | E21: DINAMIGE FORMACION TACUAREMBO | F21: =IFERROR(INDEX(Pozos!$M$2:$M$1852,MATCH(A21,Pozos!$E$2:$E$1852,0)),"") -> 145.15 | G21: =IF(AND(ISNUMBER(B21),ISNUMBER($F21)),$F21-B21,"") | H21: =IF(AND(ISNUMBER(C21),ISNUMBER($F21)),$F21-C21,"")
A22: UK000016 | B22: 28 | C22: 35 | E22: DINAMIGE // Tesis Paula Collazo | F22: =IFERROR(INDEX(Pozos!$M$2:$M$1852,MATCH(A22,Pozos!$E$2:$E$1852,0)),"") -> 140 | G22: =IF(AND(ISNUMBER(B22),ISNUMBER($F22)),$F22-B22,"") -> 112 | H22: =IF(AND(ISNUMBER(C22),ISNUMBER($F22)),$F22-C22,"") -> 105
A23: UK000016 | B23: 43 | C23: 47 | E23: DINAMIGE // Tesis Paula Collazo | F23: =IFERROR(INDEX(Pozos!$M$2:$M$1852,MATCH(A23,Pozos!$E$2:$E$1852,0)),"") -> 140 | G23: =IF(AND(ISNUMBER(B23),ISNUMBER($F23)),$F23-B23,"") -> 97 | H23: =IF(AND(ISNUMBER(C23),ISNUMBER($F23)),$F23-C23,"") -> 93
A24: UK000017 | B24: 28 | C24: 29 | E24: DINAMIGE FORMACION TACUAREMBO | F24: =IFERROR(INDEX(Pozos!$M$2:$M$1852,MATCH(A24,Pozos!$E$2:$E$1852,0)),"") -> 156.66 | G24: =IF(AND(ISNUMBER(B24),ISNUMBER($F24)),$F24-B24,"") -> 128.66 | H24: =IF(AND(ISNUMBER(C24),ISNUMBER($F24)),$F24-C24,"") -> 127.66
A25: UK000017 | B25: 32 | C25: 34 | E25: DINAMIGE FORMACION TACUAREMBO | F25: =IFERROR(INDEX(Pozos!$M$2:$M$1852,MATCH(A25,Pozos!$E$2:$E$1852,0)),"") -> 156.66 | G25: =IF(AND(ISNUMBER(B25),ISNUMBER($F25)),$F25-B25,"") -> 124.66 | H25: =IF(AND(ISNUMBER(C25),ISNUMBER($F25)),$F25-C25,"") -> 122.66
A26: UK000017 | B26: 36 | C26: 37 | E26: DINAMIGE FORMACION TACUAREMBO | F26: =IFERROR(INDEX(Pozos!$M$2:$M$1852,MATCH(A26,Pozos!$E$2:$E$1852,0)),"") -> 156.66 | G26: =IF(AND(ISNUMBER(B26),ISNUMBER($F26)),$F26-B26,"") -> 120.66 | H26: =IF(AND(ISNUMBER(C26),ISNUMBER($F26)),$F26-C26,"") -> 119.66
A27: UK000018 | B27: 29 | C27: 30 | E27: DINAMIGE FORMACION TACUAREMBO | F27: =IFERROR(INDEX(Pozos!$M$2:$M$1852,MATCH(A27,Pozos!$E$2:$E$1852,0)),"") -> 176.9 | G27: =IF(AND(ISNUMBER(B27),ISNUMBER($F27)),$F27-B27,"") -> 147.9 | H27: =IF(AND(ISNUMBER(C27),ISNUMBER($F27)),$F27-C27,"") -> 146.9
A28: UK000018 | B28: 35 | C28: 36 | E28: DINAMIGE FORMACION TACUAREMBO | F28: =IFERROR(INDEX(Pozos!$M$2:$M$1852,MATCH(A28,Pozos!$E$2:$E$1852,0)),"") -> 176.9 | G28: =IF(AND(ISNUMBER(B28),ISNUMBER($F28)),$F28-B28,"") -> 141.9 | H28: =IF(AND(ISNUMBER(C28),ISNUMBER($F28)),$F28-C28,"") -> 140.9
A29: UK000018 | B29: 39 | C29: 41 | E29: DINAMIGE FORMACION TACUAREMBO | F29: =IFERROR(INDEX(Pozos!$M$2:$M$1852,MATCH(A29,Pozos!$E$2:$E$1852,0)),"") -> 176.9 | G29: =IF(AND(ISNUMBER(B29),ISNUMBER($F29)),$F29-B29,"") -> 137.9 | H29: =IF(AND(ISNUMBER(C29),ISNUMBER($F29)),$F29-C29,"") -> 135.9
A30: UK000019 | B30: 25 | C30: 29 | E30: DINAMIGE FORMACION TACUAREMBO // Tesis Paula Collazo | F30: =IFERROR(INDEX(Pozos!$M$2:$M$1852,MATCH(A30,Pozos!$E$2:$E$1852,0)),"") -> 142 | G30: =IF(AND(ISNUMBER(B30),ISNUMBER($F30)),$F30-B30,"") -> 117 | H30: =IF(AND(ISNUMBER(C30),ISNUMBER($F30)),$F30-C30,"") -> 113
A31: UK000019 | B31: 34 | C31: 35 | E31: DINAMIGE FORMACION TACUAREMBO // Tesis Paula Collazo | F31: =IFERROR(INDEX(Pozos!$M$2:$M$1852,MATCH(A31,Pozos!$E$2:$E$1852,0)),"") -> 142 | G31: =IF(AND(ISNUMBER(B31),ISNUMBER($F31)),$F31-B31,"") -> 108 | H31: =IF(AND(ISNUMBER(C31),ISNUMBER($F31)),$F31-C31,"") -> 107
A32: UK000019 | B32: 44 | C32: 45 | E32: DINAMIGE FORMACION TACUAREMBO // Tesis Paula Collazo | F32: =IFERROR(INDEX(Pozos!$M$2:$M$1852,MATCH(A32,Pozos!$E$2:$E$1852,0)),"") -> 142 | G32: =IF(AND(ISNUMBER(B32),ISNUMBER($F32)),$F32-B32,"") -> 98 | H32: =IF(AND(ISNUMBER(C32),ISNUMBER($F32)),$F32-C32,"") -> 97
A33: UK000020 | B33: 30 | C33: 32 | E33: DINAMIGE FORMACION TACUAREMBO | F33: =IFERROR(INDEX(Pozos!$M$2:$M$1852,MATCH(A33,Pozos!$E$2:$E$1852,0)),"") -> 181.78 | G33: =IF(AND(ISNUMBER(B33),ISNUMBER($F33)),$F33-B33,"") -> 151.78 | H33: =IF(AND(ISNUMBER(C33),ISNUMBER($F33)),$F33-C33,"") -> 149.78
... A41: UK000023 | B41: 25 | C41: 28 | E41: MEVIR - MATRIN | F41: =IFERROR(INDEX(Pozos!$M$2:$M$1852,MATCH(A41,Pozos!$E$2:$E$1852,0)),"") -> 169.11 | G41: =IF(AND(ISNUMBER(B41),ISNUMBER($F41)),$F41-B41,"") -> 144.11 | H41: =IF(AND(ISNUMBER(C41),ISNUMBER($F41)),$F41-C41,"") -> 141.11
A42: UK000024 | E42: TECNOAGUA | F42: =IFERROR(INDEX(Pozos!$M$2:$M$1852,MATCH(A42,Pozos!$E$2:$E$1852,0)),"") -> 165.23 | G42: =IF(AND(ISNUMBER(B42),ISNUMBER($F42)),$F42-B42,"") | H42: =IF(AND(ISNUMBER(C42),ISNUMBER($F42)),$F42-C42,"")
A43: UK000025 | E43: Tesis Paula Collazo | F43: =IFERROR(INDEX(Pozos!$M$2:$M$1852,MATCH(A43,Pozos!$E$2:$E$1852,0)),"") -> 160 | G43: =IF(AND(ISNUMBER(B43),ISNUMBER($F43)),$F43-B43,"") | H43: =IF(AND(ISNUMBER(C43),ISNUMBER($F43)),$F43-C43,"")
A44: UK000026 | E44: Tesis Paula Collazo | F44: =IFERROR(INDEX(Pozos!$M$2:$M$1852,MATCH(A44,Pozos!$E$2:$E$1852,0)),"") -> 150 | G44: =IF(AND(ISNUMBER(B44),ISNUMBER($F44)),$F44-B44,"") | H44: =IF(AND(ISNUMBER(C44),ISNUMBER($F44)),$F44-C44,"")
A45: UK000027 | B45: 24 | C45: 30 | E45: TECNOAGUA | F45: =IFERROR(INDEX(Pozos!$M$2:$M$1852,MATCH(A45,Pozos!$E$2:$E$1852,0)),"") -> 186.94 | G45: =IF(AND(ISNUMBER(B45),ISNUMBER($F45)),$F45-B45,"") -> 162.94 | H45: =IF(AND(ISNUMBER(C45),ISNUMBER($F45)),$F45-C45,"") -> 156.94
A46: UK000027 | B46: 33 | C46: 39 | E46: TECNOAGUA | F46: =IFERROR(INDEX(Pozos!$M$2:$M$1852,MATCH(A46,Pozos!$E$2:$E$1852,0)),"") -> 186.94 | G46: =IF(AND(ISNUMBER(B46),ISNUMBER($F46)),$F46-B46,"") -> 153.94 | H46: =IF(AND(ISNUMBER(C46),ISNUMBER($F46)),$F46-C46,"") -> 147.94
A47: UK000028 | E47: DINAMIGE FORMACION TACUAREMBO | F47: =IFERROR(INDEX(Pozos!$M$2:$M$1852,MATCH(A47,Pozos!$E$2:$E$1852,0)),"") -> 179.16 | G47: =IF(AND(ISNUMBER(B47),ISNUMBER($F47)),$F47-B47,"") | H47: =IF(AND(ISNUMBER(C47),ISNUMBER($F47)),$F47-C47,"")
...

Sheet Litología
A1: Cod UK | B1: Inicio | C1: Fin | D1: Inicio Acotado | E1: Fin Acotado | F1: Litologia | G1: Formacion | H1: Fuente BD | I1: Observaciones | J1: Z_boca (m) | K1: Litologia_simplificada | L1: Unidad_hidro (propuesta) | M1: Version_tramos | N1: Control | O1: Formacion_unificada | P1: Origen_formacion
A2: UK000001 | B2: 0 | C2: 1 | D2: =IF(AND(ISNUMBER(B2),ISNUMBER($J2)),$J2-B2,"") -> 160.6 | E2: =IF(AND(ISNUMBER(C2),ISNUMBER($J2)),$J2-C2,"") -> 159.6 | F2: Suelo arenoso marrón oscuro | G2: Actual | H2: MEVIR - MATRIN | J2: =IFERROR(INDEX(Pozos!$M$2:$M$1852,MATCH(A2,Pozos!$E$2:$E$1852,0)),"") -> 160.6 | K2: Suelo / relleno | L2: Zona no saturada / cobertura | O2: Actual | P2: original
A3: UK000001 | B3: 4 | C3: 15 | D3: =IF(AND(ISNUMBER(B3),ISNUMBER($J3)),$J3-B3,"") -> 156.6 | E3: =IF(AND(ISNUMBER(C3),ISNUMBER($J3)),$J3-C3,"") -> 145.6 | F3: Sedimento arcillo arenoso violáceo | G3: Fm Tacuarembo | H3: MEVIR - MATRIN | J3: =IFERROR(INDEX(Pozos!$M$2:$M$1852,MATCH(A3,Pozos!$E$2:$E$1852,0)),"") -> 160.6 | K3: Arcilla | L3: Acuitardo / acuícludo | N3: Hueco de 3.00 m con tramo anterior | O3: Fm Tacuarembo | P3: original
A4: UK000001 | B4: 15 | C4: 18 | D4: =IF(AND(ISNUMBER(B4),ISNUMBER($J4)),$J4-B4,"") -> 145.6 | E4: =IF(AND(ISNUMBER(C4),ISNUMBER($J4)),$J4-C4,"") -> 142.6 | F4: Sedimento arenoso muy fino rosado | G4: Fm Tacuarembo | H4: MEVIR - MATRIN | J4: =IFERROR(INDEX(Pozos!$M$2:$M$1852,MATCH(A4,Pozos!$E$2:$E$1852,0)),"") -> 160.6 | K4: Arena fina | L4: Acuífero (poroso) | O4: Fm Tacuarembo | P4: original
A5: UK000001 | B5: 18 | C5: 22 | D5: =IF(AND(ISNUMBER(B5),ISNUMBER($J5)),$J5-B5,"") -> 142.6 | E5: =IF(AND(ISNUMBER(C5),ISNUMBER($J5)),$J5-C5,"") -> 138.6 | F5: Sedimento arenoso fino violáceo | G5: Fm Tacuarembo | H5: MEVIR - MATRIN | J5: =IFERROR(INDEX(Pozos!$M$2:$M$1852,MATCH(A5,Pozos!$E$2:$E$1852,0)),"") -> 160.6 | K5: Arena fina | L5: Acuífero (poroso) | O5: Fm Tacuarembo | P5: original
A6: UK000001 | B6: 22 | C6: 29 | D6: =IF(AND(ISNUMBER(B6),ISNUMBER($J6)),$J6-B6,"") -> 138.6 | E6: =IF(AND(ISNUMBER(C6),ISNUMBER($J6)),$J6-C6,"") -> 131.6 | F6: Sedimento arcillo arenoso violáceo | G6: Fm Tacuarembo | H6: MEVIR - MATRIN | J6: =IFERROR(INDEX(Pozos!$M$2:$M$1852,MATCH(A6,Pozos!$E$2:$E$1852,0)),"") -> 160.6 | K6: Arcilla | L6: Acuitardo / acuícludo | O6: Fm Tacuarembo | P6: original
A7: UK000001 | B7: 29 | C7: 30 | D7: =IF(AND(ISNUMBER(B7),ISNUMBER($J7)),$J7-B7,"") -> 131.6 | E7: =IF(AND(ISNUMBER(C7),ISNUMBER($J7)),$J7-C7,"") -> 130.6 | F7: Sedimento arcillo arenoso violáceo | G7: Fm Tacuarembo | H7: MEVIR - MATRIN | J7: =IFERROR(INDEX(Pozos!$M$2:$M$1852,MATCH(A7,Pozos!$E$2:$E$1852,0)),"") -> 160.6 | K7: Arcilla | L7: Acuitardo / acuícludo | O7: Fm Tacuarembo | P7: original
A8: UK000002 | B8: 0 | C8: 1.3 | D8: =IF(AND(ISNUMBER(B8),ISNUMBER($J8)),$J8-B8,"") -> 180.73 | E8: =IF(AND(ISNUMBER(C8),ISNUMBER($J8)),$J8-C8,"") -> 179.43 | F8: Basalto | G8: Fm Arapey | H8: TECNOAGUA | J8: =IFERROR(INDEX(Pozos!$M$2:$M$1852,MATCH(A8,Pozos!$E$2:$E$1852,0)),"") -> 180.73 | K8: Basalto | L8: Acuífero fisurado (variable) | O8: Fm Arapey | P8: original
A9: UK000002 | B9: 1.3 | C9: 44 | D9: =IF(AND(ISNUMBER(B9),ISNUMBER($J9)),$J9-B9,"") -> 179.43 | E9: =IF(AND(ISNUMBER(C9),ISNUMBER($J9)),$J9-C9,"") -> 136.73 | F9: Areniscas finas a muy finas, arcillosas, blanquecinas a rosadas | G9: Fm Tacuarembo | H9: TECNOAGUA | J9: =IFERROR(INDEX(Pozos!$M$2:$M$1852,MATCH(A9,Pozos!$E$2:$E$1852,0)),"") -> 180.73 | K9: Arenisca | L9: Acuífero (poroso consolidado) | O9: Fm Tacuarembo | P9: original
A10: UK000003 | D10: =IF(AND(ISNUMBER(B10),ISNUMBER($J10)),$J10-B10,"") | E10: =IF(AND(ISNUMBER(C10),ISNUMBER($J10)),$J10-C10,"") | F10: Sin descripcion | G10: Sin dato | H10: DINAMIGE PRIVADOS | J10: =IFERROR(INDEX(Pozos!$M$2:$M$1852,MATCH(A10,Pozos!$E$2:$E$1852,0)),"") -> 249.57 | K10: Sin descripción | P10: sin dato
A11: UK000004 | D11: =IF(AND(ISNUMBER(B11),ISNUMBER($J11)),$J11-B11,"") | E11: =IF(AND(ISNUMBER(C11),ISNUMBER($J11)),$J11-C11,"") | F11: Sin descripcion | G11: Sin dato | H11: DINAMIGE PRIVADOS | J11: =IFERROR(INDEX(Pozos!$M$2:$M$1852,MATCH(A11,Pozos!$E$2:$E$1852,0)),"") -> 254.03 | K11: Sin descripción | P11: sin dato
A12: UK000005 | B12: 0 | C12: 45 | D12: =IF(AND(ISNUMBER(B12),ISNUMBER($J12)),$J12-B12,"") -> 133.52 | E12: =IF(AND(ISNUMBER(C12),ISNUMBER($J12)),$J12-C12,"") -> 88.52 | F12: Sin descripcion | G12: Sin dato | H12: DJ DINAGUA | J12: =IFERROR(INDEX(Pozos!$M$2:$M$1852,MATCH(A12,Pozos!$E$2:$E$1852,0)),"") -> 133.52 | K12: Sin descripción | P12: sin dato
A13: UK000006 | B13: 0 | C13: 2 | D13: =IF(AND(ISNUMBER(B13),ISNUMBER($J13)),$J13-B13,"") -> 158.71 | E13: =IF(AND(ISNUMBER(C13),ISNUMBER($J13)),$J13-C13,"") -> 156.71 | F13: Suelo y sedimentos areno arcillosos, color pardo | G13: Actual | H13: Tecnoagua | J13: =IFERROR(INDEX(Pozos!$M$2:$M$1852,MATCH(A13,Pozos!$E$2:$E$1852,0)),"") -> 158.71 | K13: Suelo / relleno | L13: Zona no saturada / cobertura | O13: Actual | P13: original
A14: UK000006 | B14: 2 | C14: 37 | D14: =IF(AND(ISNUMBER(B14),ISNUMBER($J14)),$J14-B14,"") -> 156.71 | E14: =IF(AND(ISNUMBER(C14),ISNUMBER($J14)),$J14-C14,"") -> 121.71 | F14: Areniscas finas a muy finas, arcillosas, colores blanquecinos a rosados | G14: Fm Tacuarembo | H14: Tecnoagua | J14: =IFERROR(INDEX(Pozos!$M$2:$M$1852,MATCH(A14,Pozos!$E$2:$E$1852,0)),"") -> 158.71 | K14: Arenisca | L14: Acuífero (poroso consolidado) | O14: Fm Tacuarembo | P14: original
A15: UK000006 | B15: 37 | C15: 55 | D15: =IF(AND(ISNUMBER(B15),ISNUMBER($J15)),$J15-B15,"") -> 121.71 | E15: =IF(AND(ISNUMBER(C15),ISNUMBER($J15)),$J15-C15,"") -> 103.71 | F15: Areniscas muy finas, arcillosas y siltitos rojizos | G15: Fm Tacuarembo | H15: Tecnoagua | J15: =IFERROR(INDEX(Pozos!$M$2:$M$1852,MATCH(A15,Pozos!$E$2:$E$1852,0)),"") -> 158.71 | K15: Arenisca | L15: Acuífero (poroso consolidado) | O15: Fm Tacuarembo | P15: original
A16: UK000007 | B16: 0 | C16: 18 | D16: =IF(AND(ISNUMBER(B16),ISNUMBER($J16)),$J16-B16,"") -> 195.12 | E16: =IF(AND(ISNUMBER(C16),ISNUMBER($J16)),$J16-C16,"") -> 177.12 | F16: Areniscas muy finas a finas, arcillosas, ocre pálido | G16: Fm Tacuarembo | H16: TECNOAGUA | J16: =IFERROR(INDEX(Pozos!$M$2:$M$1852,MATCH(A16,Pozos!$E$2:$E$1852,0)),"") -> 195.12 | K16: Arenisca | L16: Acuífero (poroso consolidado) | O16: Fm Tacuarembo | P16: original
A17: UK000007 | B17: 18 | C17: 24 | D17: =IF(AND(ISNUMBER(B17),ISNUMBER($J17)),$J17-B17,"") -> 177.12 | E17: =IF(AND(ISNUMBER(C17),ISNUMBER($J17)),$J17-C17,"") -> 171.12 | F17: Areniscas finas a muy finas, arcillosas, rosado | G17: Fm Tacuarembo | H17: TECNOAGUA | J17: =IFERROR(INDEX(Pozos!$M$2:$M$1852,MATCH(A17,Pozos!$E$2:$E$1852,0)),"") -> 195.12 | K17: Arenisca | L17: Acuífero (poroso consolidado) | O17: Fm Tacuarembo | P17: original
A18: UK000007 | B18: 24 | C18: 30 | D18: =IF(AND(ISNUMBER(B18),ISNUMBER($J18)),$J18-B18,"") -> 171.12 | E18: =IF(AND(ISNUMBER(C18),ISNUMBER($J18)),$J18-C18,"") -> 165.12 | F18: Areniscas finas, arcillosas, rojizas | G18: Fm Tacuarembo | H18: TECNOAGUA | J18: =IFERROR(INDEX(Pozos!$M$2:$M$1852,MATCH(A18,Pozos!$E$2:$E$1852,0)),"") -> 195.12 | K18: Arenisca | L18: Acuífero (poroso consolidado) | O18: Fm Tacuarembo | P18: original
A19: UK000007 | B19: 30 | C19: 53 | D19: =IF(AND(ISNUMBER(B19),ISNUMBER($J19)),$J19-B19,"") -> 165.12 | E19: =IF(AND(ISNUMBER(C19),ISNUMBER($J19)),$J19-C19,"") -> 142.12 | F19: Areniscas finas, arcillosas, ocre palido | G19: Fm Tacuarembo | H19: TECNOAGUA | J19: =IFERROR(INDEX(Pozos!$M$2:$M$1852,MATCH(A19,Pozos!$E$2:$E$1852,0)),"") -> 195.12 | K19: Arenisca | L19: Acuífero (poroso consolidado) | O19: Fm Tacuarembo | P19: original
A20: UK000007 | B20: 53 | C20: 58 | D20: =IF(AND(ISNUMBER(B20),ISNUMBER($J20)),$J20-B20,"") -> 142.12 | E20: =IF(AND(ISNUMBER(C20),ISNUMBER($J20)),$J20-C20,"") -> 137.12 | F20: Areniscas finas a medias, blanquecinas | G20: Fm Tacuarembo | H20: TECNOAGUA | J20: =IFERROR(INDEX(Pozos!$M$2:$M$1852,MATCH(A20,Pozos!$E$2:$E$1852,0)),"") -> 195.12 | K20: Arenisca | L20: Acuífero (poroso consolidado) | O20: Fm Tacuarembo | P20: original
A21: UK000008 | B21: 0 | C21: 68 | D21: =IF(AND(ISNUMBER(B21),ISNUMBER($J21)),$J21-B21,"") -> 154.78 | E21: =IF(AND(ISNUMBER(C21),ISNUMBER($J21)),$J21-C21,"") -> 86.78 | F21: Arenisca | G21: Fm Tacuarembo | H21: DINAMIGE FORMACION TACUAREMBO | J21: =IFERROR(INDEX(Pozos!$M$2:$M$1852,MATCH(A21,Pozos!$E$2:$E$1852,0)),"") -> 154.78 | K21: Arenisca | L21: Acuífero (poroso consolidado) | O21: Fm Tacuarembo | P21: original
A22: UK000161 | B22: 0 | C22: 65 | D22: =IF(AND(ISNUMBER(B22),ISNUMBER($J22)),$J22-B22,"") -> 164.7 | E22: =IF(AND(ISNUMBER(C22),ISNUMBER($J22)),$J22-C22,"") -> 99.7 | F22: Areniscas finas a muy finas, arcillosas, colores blancos y rosados | G22: Fm Tacuarembo | H22: TECNOAGUA | J22: =IFERROR(INDEX(Pozos!$M$2:$M$1852,MATCH(A22,Pozos!$E$2:$E$1852,0)),"") -> 164.7 | K22: Arenisca | L22: Acuífero (poroso consolidado) | M22: 1 | N22: Litología cargada 2 veces (versión 1) | O22: Fm Tacuarembo | P22: original
A23: UK000010 | B23: 0 | C23: 2 | D23: =IF(AND(ISNUMBER(B23),ISNUMBER($J23)),$J23-B23,"") -> 176.92 | E23: =IF(AND(ISNUMBER(C23),ISNUMBER($J23)),$J23-C23,"") -> 174.92 | F23: Suelo | G23: Actual | H23: TECNOAGUA | J23: =IFERROR(INDEX(Pozos!$M$2:$M$1852,MATCH(A23,Pozos!$E$2:$E$1852,0)),"") -> 176.92 | K23: Suelo / relleno | L23: Zona no saturada / cobertura | O23: Actual | P23: original
A24: UK000010 | B24: 2 | C24: 8 | D24: =IF(AND(ISNUMBER(B24),ISNUMBER($J24)),$J24-B24,"") -> 174.92 | E24: =IF(AND(ISNUMBER(C24),ISNUMBER($J24)),$J24-C24,"") -> 168.92 | F24: Arcilla pardo claro | G24: Fm Tacuarembo | H24: TECNOAGUA | J24: =IFERROR(INDEX(Pozos!$M$2:$M$1852,MATCH(A24,Pozos!$E$2:$E$1852,0)),"") -> 176.92 | K24: Arcilla | L24: Acuitardo / acuícludo | O24: Fm Tacuarembo | P24: original
A25: UK000010 | B25: 8 | C25: 15 | D25: =IF(AND(ISNUMBER(B25),ISNUMBER($J25)),$J25-B25,"") -> 168.92 | E25: =IF(AND(ISNUMBER(C25),ISNUMBER($J25)),$J25-C25,"") -> 161.92 | F25: Areniscas finas a medias, arcillosas, litificadas, rosadas | G25: Fm Tacuarembo | H25: TECNOAGUA | J25: =IFERROR(INDEX(Pozos!$M$2:$M$1852,MATCH(A25,Pozos!$E$2:$E$1852,0)),"") -> 176.92 | K25: Arenisca | L25: Acuífero (poroso consolidado) | O25: Fm Tacuarembo | P25: original
A26: UK000010 | B26: 15 | C26: 23 | D26: =IF(AND(ISNUMBER(B26),ISNUMBER($J26)),$J26-B26,"") -> 161.92 | E26: =IF(AND(ISNUMBER(C26),ISNUMBER($J26)),$J26-C26,"") -> 153.92 | F26: Areniscas muy finas, arcillosas, litificadas, rosadas | G26: Fm Tacuarembo | H26: TECNOAGUA | J26: =IFERROR(INDEX(Pozos!$M$2:$M$1852,MATCH(A26,Pozos!$E$2:$E$1852,0)),"") -> 176.92 | K26: Arenisca | L26: Acuífero (poroso consolidado) | O26: Fm Tacuarembo | P26: original
A27: UK000010 | B27: 23 | C27: 25 | D27: =IF(AND(ISNUMBER(B27),ISNUMBER($J27)),$J27-B27,"") -> 153.92 | E27: =IF(AND(ISNUMBER(C27),ISNUMBER($J27)),$J27-C27,"") -> 151.92 | F27: Areniscas finas a medias, arcillosas, litificadas, rosadas | G27: Fm Tacuarembo | H27: TECNOAGUA | J27: =IFERROR(INDEX(Pozos!$M$2:$M$1852,MATCH(A27,Pozos!$E$2:$E$1852,0)),"") -> 176.92 | K27: Arenisca | L27: Acuífero (poroso consolidado) | O27: Fm Tacuarembo | P27: original
A28: UK000010 | B28: 25 | C28: 31 | D28: =IF(AND(ISNUMBER(B28),ISNUMBER($J28)),$J28-B28,"") -> 151.92 | E28: =IF(AND(ISNUMBER(C28),ISNUMBER($J28)),$J28-C28,"") -> 145.92 | F28: Areniscas finas a muy finas, arcillosas, litificadas. Rosadas | G28: Fm Tacuarembo | H28: TECNOAGUA | J28: =IFERROR(INDEX(Pozos!$M$2:$M$1852,MATCH(A28,Pozos!$E$2:$E$1852,0)),"") -> 176.92 | K28: Arenisca | L28: Acuífero (poroso consolidado) | O28: Fm Tacuarembo | P28: original
A29: UK000010 | B29: 31 | C29: 33 | D29: =IF(AND(ISNUMBER(B29),ISNUMBER($J29)),$J29-B29,"") -> 145.92 | E29: =IF(AND(ISNUMBER(C29),ISNUMBER($J29)),$J29-C29,"") -> 143.92 | F29: Areniscas medias a gruesas, arcillosas, litificadas, rojizas | G29: Fm Tacuarembo | H29: TECNOAGUA | J29: =IFERROR(INDEX(Pozos!$M$2:$M$1852,MATCH(A29,Pozos!$E$2:$E$1852,0)),"") -> 176.92 | K29: Arenisca | L29: Acuífero (poroso consolidado) | O29: Fm Tacuarembo | P29: original
A30: UK000010 | B30: 33 | C30: 36 | D30: =IF(AND(ISNUMBER(B30),ISNUMBER($J30)),$J30-B30,"") -> 143.92 | E30: =IF(AND(ISNUMBER(C30),ISNUMBER($J30)),$J30-C30,"") -> 140.92 | F30: Areniscas muy finas, arcillosas, litificadas, rosadas | G30: Fm Tacuarembo | H30: TECNOAGUA | J30: =IFERROR(INDEX(Pozos!$M$2:$M$1852,MATCH(A30,Pozos!$E$2:$E$1852,0)),"") -> 176.92 | K30: Arenisca | L30: Acuífero (poroso consolidado) | O30: Fm Tacuarembo | P30: original
A31: UK000010 | B31: 36 | C31: 38 | D31: =IF(AND(ISNUMBER(B31),ISNUMBER($J31)),$J31-B31,"") -> 140.92 | E31: =IF(AND(ISNUMBER(C31),ISNUMBER($J31)),$J31-C31,"") -> 138.92 | F31: Areniscas finas a medias,arcillosas, litificadas, rosadas | G31: Fm Tacuarembo | H31: TECNOAGUA | J31: =IFERROR(INDEX(Pozos!$M$2:$M$1852,MATCH(A31,Pozos!$E$2:$E$1852,0)),"") -> 176.92 | K31: Arenisca | L31: Acuífero (poroso consolidado) | O31: Fm Tacuarembo | P31: original
A32: UK000010 | B32: 38 | C32: 40 | D32: =IF(AND(ISNUMBER(B32),ISNUMBER($J32)),$J32-B32,"") -> 138.92 | E32: =IF(AND(ISNUMBER(C32),ISNUMBER($J32)),$J32-C32,"") -> 136.92 | F32: Areniscas finas a muy finas,arcillosas, litificadas, rosadas | G32: Fm Tacuarembo | H32: TECNOAGUA | J32: =IFERROR(INDEX(Pozos!$M$2:$M$1852,MATCH(A32,Pozos!$E$2:$E$1852,0)),"") -> 176.92 | K32: Arenisca | L32: Acuífero (poroso consolidado) | O32: Fm Tacuarembo | P32: original
A33: UK000011 | B33: 0 | C33: 2 | D33: =IF(AND(ISNUMBER(B33),ISNUMBER($J33)),$J33-B33,"") -> 162.68 | E33: =IF(AND(ISNUMBER(C33),ISNUMBER($J33)),$J33-C33,"") -> 160.68 | F33: Arcilla marron | G33: Fm Tacuarembo | H33: DINAMIGE FORMACION TACUAREMBO | J33: =IFERROR(INDEX(Pozos!$M$2:$M$1852,MATCH(A33,Pozos!$E$2:$E$1852,0)),"") -> 162.68 | K33: Arcilla | L33: Acuitardo / acuícludo | O33: Fm Tacuarembo | P33: original
A34: UK000011 | B34: 2 | C34: 42.5 | D34: =IF(AND(ISNUMBER(B34),ISNUMBER($J34)),$J34-B34,"") -> 160.68 | E34: =IF(AND(ISNUMBER(C34),ISNUMBER($J34)),$J34-C34,"") -> 120.18 | F34: Areniscas grises y rosadas por capas | G34: Fm Tacuarembo | H34: DINAMIGE FORMACION TACUAREMBO | J34: =IFERROR(INDEX(Pozos!$M$2:$M$1852,MATCH(A34,Pozos!$E$2:$E$1852,0)),"") -> 162.68 | K34: Arenisca | L34: Acuífero (poroso consolidado) | O34: Fm Tacuarembo | P34: original
A35: UK000012 | D35: =IF(AND(ISNUMBER(B35),ISNUMBER($J35)),$J35-B35,"") | E35: =IF(AND(ISNUMBER(C35),ISNUMBER($J35)),$J35-C35,"") | F35: Sin descripcion | G35: Sin dato | H35: DINAMIGE FORMACION TACUAREMBO | J35: =IFERROR(INDEX(Pozos!$M$2:$M$1852,MATCH(A35,Pozos!$E$2:$E$1852,0)),"") -> 147.1 | K35: Sin descripción | P35: sin dato
A36: UK000013 | B36: 0 | C36: 14 | D36: =IF(AND(ISNUMBER(B36),ISNUMBER($J36)),$J36-B36,"") -> 135.04 | E36: =IF(AND(ISNUMBER(C36),ISNUMBER($J36)),$J36-C36,"") -> 121.04 | F36: Arenisca | G36: Actual | H36: DINAMIGE FORMACION TACUAREMBO | J36: =IFERROR(INDEX(Pozos!$M$2:$M$1852,MATCH(A36,Pozos!$E$2:$E$1852,0)),"") -> 135.04 | K36: Arenisca | L36: Acuífero (poroso consolidado) | O36: Actual | P36: original
A37: UK000013 | B37: 14 | C37: 20 | D37: =IF(AND(ISNUMBER(B37),ISNUMBER($J37)),$J37-B37,"") -> 121.04 | E37: =IF(AND(ISNUMBER(C37),ISNUMBER($J37)),$J37-C37,"") -> 115.04 | F37: Arcilla | G37: Fm Tacuarembo | H37: DINAMIGE FORMACION TACUAREMBO | J37: =IFERROR(INDEX(Pozos!$M$2:$M$1852,MATCH(A37,Pozos!$E$2:$E$1852,0)),"") -> 135.04 | K37: Arcilla | L37: Acuitardo / acuícludo | O37: Fm Tacuarembo | P37: original
A38: UK000013 | B38: 20 | C38: 27.5 | D38: =IF(AND(ISNUMBER(B38),ISNUMBER($J38)),$J38-B38,"") -> 115.04 | E38: =IF(AND(ISNUMBER(C38),ISNUMBER($J38)),$J38-C38,"") -> 107.54 | F38: Arcilla con piedras | G38: Fm Tacuarembo | H38: DINAMIGE FORMACION TACUAREMBO | J38: =IFERROR(INDEX(Pozos!$M$2:$M$1852,MATCH(A38,Pozos!$E$2:$E$1852,0)),"") -> 135.04 | K38: Arcilla | L38: Acuitardo / acuícludo | O38: Fm Tacuarembo | P38: original
A39: UK000014 | B39: 0 | C39: 18 | D39: =IF(AND(ISNUMBER(B39),ISNUMBER($J39)),$J39-B39,"") -> 170 | E39: =IF(AND(ISNUMBER(C39),ISNUMBER($J39)),$J39-C39,"") -> 152 | F39: Arenisca Fina a Media, arcillosas, rojizas | G39: Actual | H39: Tesis Paula Collazo | J39: =IFERROR(INDEX(Pozos!$M$2:$M$1852,MATCH(A39,Pozos!$E$2:$E$1852,0)),"") -> 170 | K39: Arenisca | L39: Acuífero (poroso consolidado) | M39: 1 | N39: Litología cargada 2 veces (versión 1) | O39: Actual | P39: original
A40: UK000014 | B40: 18 | C40: 30 | D40: =IF(AND(ISNUMBER(B40),ISNUMBER($J40)),$J40-B40,"") -> 152 | E40: =IF(AND(ISNUMBER(C40),ISNUMBER($J40)),$J40-C40,"") -> 140 | F40: Arenisca Fina a Media Fina, | G40: Fm Tacuarembo | H40: Tesis Paula Collazo | J40: =IFERROR(INDEX(Pozos!$M$2:$M$1852,MATCH(A40,Pozos!$E$2:$E$1852,0)),"") -> 170 | K40: Arenisca | L40: Acuífero (poroso consolidado) | M40: 1 | N40: Litología cargada 2 veces (versión 1) | O40: Fm Tacuarembo | P40: original
...

Sheet Hidroquímica
A1: Cod UK | B1: Fecha | C1: Año | D1: Observaciones | E1: pH | F1: Alcalinidad Carbonatada (mg CaCO3/L) | G1: HCO3 mg/l | H1: Alcalinidad Bicarbonatada (mg CaCO3/L) | I1: Alcalinidad Total (mg CaCO3/L) | J1: Temp.agua (Cº) | K1: Conductividad electrica (microS/cm) | L1: O2 disuelto (mg/L) | M1: CO2 (mg/L) | N1: PO4 (mg/L) (I) | O1: N-NO2 (mg/L) (I) | P1: Sólid. totales (mg/l) | Q1: Sólidos totales disueltos (mg/L) | R1: Dureza Total (mg CaCO3/L) | S1: Cl- (mg Cl-/L) | T1: SO42- (mg SO42-/L) | U1: Fosforo total (mg/L) | V1: DBO5 (mg O2/L) | W1: DQO (mg O2/L) | X1: Carbono org. (mg/L) | Y1: F- (mg F-/L) | Z1: Ca2+ (mg Ca2+/L) | AA1: Na+ (mg Na+/L) | AB1: K+(mg K+/L) | AC1: Mg2+ (mg Mg2+/L) | AD1: Si (mg/L) | AE1: Al disuelto (mg/L) | AF1: Al (mg/L) | AG1: Li disuelto (mg/L) | AH1: Li (mg/L) | AI1: As disuelto(ug/L) | AJ1: As (ug/L) | AK1: Ba disuelto (mg/L) | AL1: Ba (mg/L) | AM1: B disuelto (mg/L) | AN1: B (mg/L) | AO1: Br (mg/L) | AP1: Cd disuelto (mg/L) | AQ1: Cd (mg/L) | AR1: Zn disuelto (mg/L) | AS1: Zn (mg/L) | AT1: Cu disuelto (mg/L) | AU1: Cu (mg/L) | AV1: Cr Total Soluble (mg/L) | AW1: Cr VI (mg/L) | AX1: Fe disuelto (mg/L) | AY1: Fe total (mg/L) | AZ1: Mn disuelto (mg/L) | BA1: Mn (mg/L) | BB1: Hg disuelto (ug/L) | BC1: Hg (ug/L) | BD1: Ni disuelto (mg/L) | BE1: Ni (mg/L) | BF1: Pb disuelto (ug/L) | BG1: Pb (ug/L) | BH1: Se disuelto (mg/L) | BI1: Se (mg/L) | BJ1: NO3 (mg/L) | BK1: N-NH4 (mg/L) | BL1: Ag | BM1: Mo | BN1: Sb | BO1: Ti | BP1: Th | BQ1: U | BR1: Be | BS1: V | BT1: Mn | BU1: Co | BV1: Ni | BW1: Error % | BX1: Fuente | BY1: He x 10-8 (cm3/g) | BZ1: Ne x 10-7 (cm3/g) | CA1: Ar x 10-4 (cm3/g) | CB1: Kr x 10-8 (cm3/g) | CC1: O2 x 10-3 (cm3/g) | CD1: N2 x 10-2 (cm3/g) | CE1: CO2 x10-3 (cm3/g) | CF1: δ18O VSMOW(‰) | CG1: δ2H VSMOW(‰) | CH1: NGT (°C) | CI1: △Ne (%) | CJ1: Fuente
A2: UK001014 | B2: 34601 | C2: 1994 | D2: Fecha de analisis 10/10/1994, Dato original Nitrito=0.0084 | E2: 7 | F2: 0 | I2: 176.6 | K2: 391 | O2: 0.0025536 | R2: 192.1 | S2: 2.8 | T2: 6 | Z2: 47.9 | AC2: 17.4 | BJ2: 75 | BK2: 0.032 | BX2: Dinamige
A3: UK001020 | B3: 27065 | C3: 1974 | D3: Fecha de analisis 20/2/1974 // En fuente original se observa "Muestra con filtraciones de 5m00, 19m00, 49m00 y 70m00." | E3: 7 | F3: 0 | I3: 80 | O3: 0 | R3: 72 | S3: 12.8 | BJ3: 10.2 | BX3: Dinamige
A4: UK001020 | B4: 27065 | C4: 1974 | D4: Fecha de analisis 20/2/1974 | E4: 7 | F4: 0 | I4: 78 | O4: 0 | R4: 72 | S4: 13.8 | BJ4: 0 | BK4: 0.064 | BX4: Dinamige
A5: UK001021 | B5: 27208 | C5: 1974 | D5: Fecha de analisis 15/7/1974 | E5: 6.6 | F5: 0 | I5: 54.5 | O5: 0 | R5: 42 | S5: 5.8 | T5: 0 | BJ5: 0 | BK5: 0.1
A6: UK001021 | B6: 44761 | C6: 2022 | E6: 6.6 | R6: 42 | S6: 5.8 | T6: 0 | BJ6: 0 | BX6: Dinamige
A7: UK001021 | B7: 45005 | C7: 2023 | J7: 9 | BA7: 0.0006 | BX7: Dinamige | CJ7: Techera
A8: UK001033 | E8: 5.9 | G8: 22.1 | K8: 50 | R8: 8.7 | S8: 1.1 | T8: 2.7 | Z8: 2.7 | AC8: 0.4 | BJ8: 0.8 | BX8: Recopilación Carrión - tabla uk_quiica_recopilacion-utm-revisado
A9: UK001053 | B9: 45035 | C9: 2023 | J9: 4 | AZ9: 0.0006 | BX9: Dinamige
A10: UK001064 | E10: 6 | I10: 248.8 | R10: 273.3 | S10: 10.8 | T10: 7.2 | Z10: 84.5 | AC10: 14.9 | BJ10: 102.05 | BX10: Proyecto SAG ANII, Dinamige
